Workbook

Sheet Listas
B5: HORARIOS
B6: 0 | C6: 0
A7: 1 | B7: Completa Diurna | C7: 8
A8: 2 | B8: Completa Tarde Noche | C8: 7
A9: 3 | B9: Completa Nocturna | C9: 6
A10: 4 | B10: Parcial Diurna | C10: 7
A11: 5 | B11: Parcial Tarde Noche | C11: 6.125
A12: 6 | B12: Parcial Nocturna | C12: 5.25
B14: PUESTOS DE QUIEN LAS LABORARÁ
B16: 0
A17: 1 | B17: Misceláneo (a)
A18: 2 | B18: Lead
A19: 3 | B19: Coordinador
A20: 4 | B20: Supervisor Mant.
A21: 5 | B21: Op. Mant.
A22: 6 | B22: Jardinero
B24: TIPOS DE HORA
B26: 0 | N26: Lead | O26: 1508.55 | P26: 9.5 | Q26: =+O26*P26 -> 14331.225
A27: 1 | B27: Ordinarias y feriados | N27: Misc | O27: 1227.66 | P27: 9.5 | Q27: =+O27*P27 -> 11662.77
A28: 2 | B28: Extras 1.5 | O28: =+O26-O27 -> 280.89 | P28: =+P26-P27 -> 0 | Q28: =+Q26-Q27 -> 2668.455
A29: 3 | B29: Extras Dobles | O29: =+O28/O27 -> 0.22880113
N31: Coordinador | O31: =((460470/30)/8) -> 1918.625 | P31: 9.5 | Q31: =+O31*P31 -> 18226.938
B32: JORNADA | N32: Misc | O32: 1227.66 | P32: 9.5 | Q32: =+O32*P32 -> 11662.77
O33: =+O31-O32 -> 690.965 | P33: =+P31-P32 -> 0 | Q33: =+Q31-Q32 -> 6564.1675
B34: 0 | O34: =+O33/O32 -> 0.56283091
A35: 1 | B35: Completa
A36: 2 | B36: Parcial | N36: Supervisor | O36: =((598300/30)/8) -> 2492.9167 | P36: 9.5 | Q36: =+O36*P36 -> 23682.708
N37: Misc | O37: 1227.66 | P37: 9.5 | Q37: =+O37*P37 -> 11662.77
B38: HORARIO GENERAL | O38: =+O36-O37 -> 1265.2567 | P38: =+P36-P37 -> 0 | Q38: =+Q36-Q37 -> 12019.938
O39: =+O38/O37 -> 1.0306247
B40: 0
A41: 1 | B41: Diurno | N41: Op. Mant | O41: =((387000/30)/8) -> 1612.5 | P41: 9.5 | Q41: =+O41*P41 -> 15318.75
A42: 2 | B42: Tarde Noche | N42: Misc | O42: 1227.66 | P42: 9.5 | Q42: =+O42*P42 -> 11662.77
A43: 3 | B43: Nocturno | O43: =+O41-O42 -> 384.84 | P43: =+P41-P42 -> 0 | Q43: =+Q41-Q42 -> 3655.98
O44: =+O43/O42 -> 0.31347441
N46: Jardinero | O46: =((328251/30)/8) -> 1367.7125 | P46: 9.5 | Q46: =+O46*P46 -> 12993.269
N47: Misc | O47: 1227.66 | P47: 9.5 | Q47: =+O47*P47 -> 11662.77
O48: =+O46-O47 -> 140.0525 | P48: =+P46-P47 -> 0 | Q48: =+Q46-Q47 -> 1330.4988
O49: =+O48/O47 -> 0.11408085

Sheet Res
D3: Total de Horas Ordinarias Autorizadas por Día. | E3: Total de Horas Ordinarias Consumidas en el día | F3: Saldos Diarios | G3: Saldo Mensual
B4: Día # 1 | C4: =+'1'!F4 -> 46076 | D4: =+'1'!Z4 -> 0 | E4: =+'1'!AA4 -> 0 | F4: =+'1'!AF4 -> 0 | G4: =SUM(D4:D38)+SUM(E4:E38) -> 0
B5: Día # 2 | C5: =+C4+1 -> 46077 | D5: =+'2'!Z4 -> 0 | E5: =+'2'!AA4 -> 0 | F5: =+'2'!$AF$4 -> 0
B6: Día # 3 | C6: =+C5+1 -> 46078 | D6: =+'3'!$Z$4 -> 0 | E6: =+'3'!$AA$4 -> 0 | F6: =+'3'!$AF$4 -> 0
B7: Día # 4 | C7: =+C6+1 -> 46079 | D7: =+'4'!$Z$4 -> 0 | E7: =+'4'!$AA$4 -> 0 | F7: =+'4'!$AF$4 -> 0
B8: Día # 5 | C8: =+C7+1 -> 46080 | D8: =+'5'!$Z$4 -> 0 | E8: =+'5'!$AA$4 -> 0 | F8: =+'5'!$AF$4 -> 0
B9: Día # 6 | C9: =+C8+1 -> 46081 | D9: =+'6'!$Z$4 -> 0 | E9: =+'6'!$AA$4 -> 0 | F9: =+'6'!$AF$4 -> 0
B10: Día # 7 | C10: =+C9+1 -> 46082 | D10: =+'7'!$Z$4 -> 0 | E10: =+'7'!$AA$4 -> 0 | F10: =+'7'!$AF$4 -> 0
B11: Día # 8 | C11: =+C10+1 -> 46083 | D11: =+'8'!$Z$4 -> 0 | E11: =+'8'!$AA$4 -> 0 | F11: =+'8'!$AF$4 -> 0
B12: Día # 9 | C12: =+C11+1 -> 46084 | D12: =+'9'!$Z$4 -> 0 | E12: =+'9'!$AA$4 -> 0 | F12: =+'9'!$AF$4 -> 0
B13: Día # 10 | C13: =+C12+1 -> 46085 | D13: =+'10'!$Z$4 -> 0 | E13: =+'10'!$AA$4 -> 0 | F13: =+'10'!$AF$4 -> 0
B14: Día # 11 | C14: =+C13+1 -> 46086 | D14: =+'11'!$Z$4 -> 0 | E14: =+'11'!$AA$4 -> 0 | F14: =+'11'!$AF$4 -> 0
B15: Día # 12 | C15: =+C14+1 -> 46087 | D15: =+'12'!$Z$4 -> 0 | E15: =+'12'!$AA$4 -> 0 | F15: =+'12'!$AF$4 -> 0
B16: Día # 13 | C16: =+C15+1 -> 46088 | D16: =+'13'!$Z$4 -> 0 | E16: =+'13'!$AA$4 -> 0 | F16: =+'13'!$AF$4 -> 0
B17: Día # 14 | C17: =+C16+1 -> 46089 | D17: =+'14'!$Z$4 -> 0 | E17: =+'14'!$AA$4 -> 0 | F17: =+'14'!$AF$4 -> 0
B18: Día # 15 | C18: =+C17+1 -> 46090 | D18: =+'15'!$Z$4 -> 0 | E18: =+'15'!$AA$4 -> 0 | F18: =+'15'!$AF$4 -> 0
B19: Día # 16 | C19: =+C18+1 -> 46091 | D19: =+'16'!$Z$4 -> 0 | E19: =+'16'!$AA$4 -> 0 | F19: =+'16'!$AF$4 -> 0
B20: Día # 17 | C20: =+C19+1 -> 46092 | D20: =+'17'!$Z$4 -> 0 | E20: =+'17'!$AA$4 -> 0 | F20: =+'17'!$AF$4 -> 0
B21: Día # 18 | C21: =+C20+1 -> 46093 | D21: =+'18'!$Z$4 -> 0 | E21: =+'18'!$AA$4 -> 0 | F21: =+'18'!$AF$4 -> 0
B22: Día # 19 | C22: =+C21+1 -> 46094 | D22: =+'19'!$Z$4 -> 0 | E22: =+'19'!$AA$4 -> 0 | F22: =+'19'!$AF$4 -> 0
B23: Día # 20 | C23: =+C22+1 -> 46095 | D23: =+'20'!$Z$4 -> 0 | E23: =+'20'!$AA$4 -> 0 | F23: =+'20'!$AF$4 -> 0
B24: Día # 21 | C24: =+C23+1 -> 46096 | D24: =+'21'!$Z$4 -> 0 | E24: =+'21'!$AA$4 -> 0 | F24: =+'21'!$AF$4 -> 0
B25: Día # 22 | C25: =+C24+1 -> 46097 | D25: =+'22'!$Z$4 -> 0 | E25: =+'22'!$AA$4 -> 0 | F25: =+'22'!$AF$4 -> 0
B26: Día # 23 | C26: =+C25+1 -> 46098 | D26: =+'23'!$Z$4 -> 0 | E26: =+'23'!$AA$4 -> 0 | F26: =+'23'!$AF$4 -> 0
B27: Día # 24 | C27: =+C26+1 -> 46099 | D27: =+'24'!$Z$4 -> 0 | E27: =+'24'!$AA$4 -> 0 | F27: =+'24'!$AF$4 -> 0
B28: Día # 25 | C28: =+C27+1 -> 46100 | D28: =+'25'!$Z$4 -> 0 | E28: =+'25'!$AA$4 -> 0 | F28: =+'25'!$AF$4 -> 0
B29: Día # 26 | C29: =+C28+1 -> 46101 | D29: =+'26'!$Z$4 -> 0 | E29: =+'26'!$AA$4 -> 0 | F29: =+'26'!$AF$4 -> 0
B30: Día # 27 | C30: =+C29+1 -> 46102 | D30: =+'27'!$Z$4 -> 0 | E30: =+'27'!$AA$4 -> 0 | F30: =+'27'!$AF$4 -> 0
B31: Día # 28 | C31: =+C30+1 -> 46103 | D31: =+'28'!$Z$4 -> 0 | E31: =+'28'!$AA$4 -> 0 | F31: =+'28'!$AF$4 -> 0
B32: Día # 29 | C32: =+C31+1 -> 46104 | D32: =+'29'!$Z$4 -> 0 | E32: =+'29'!$AA$4 -> 0 | F32: =+'29'!$AF$4 -> 0
B33: Día # 30 | C33: =+C32+1 -> 46105 | D33: =+'30'!$Z$4 -> 0 | E33: =+'30'!$AA$4 -> 0 | F33: =+'30'!$AF$4 -> 0
B34: Día # 31 | C34: =+C33+1 -> 46106 | D34: =+'31'!$Z$4 -> 0 | E34: =+'31'!$AA$4 -> 0 | F34: =+'31'!$AF$4 -> 0
B35: Día # 32 | C35: =+C34+1 -> 46107 | D35: =+'32'!$Z$4 -> 0 | E35: =+'32'!$AA$4 -> 0 | F35: =+'32'!$AF$4 -> 0
B36: Día # 33 | C36: =+C35+1 -> 46108 | D36: =+'33'!$Z$4 -> 0 | E36: =+'33'!$AA$4 -> 0 | F36: =+'33'!$AF$4 -> 0
B37: Día # 34 | C37: =+C36+1 -> 46109 | D37: =+'34'!$Z$4 -> 0 | E37: =+'34'!$AA$4 -> 0 | F37: =+'34'!$AF$4 -> 0
B38: Día # 35 | C38: =+C37+1 -> 46110 | D38: =+'35'!$Z$4 -> 0 | E38: =+'35'!$AA$4 -> 0 | F38: =+'35'!$AF$4 -> 0

Sheet 1
F2: FECHA | G2: PROYECTO | V2: RIGE A PARTIR DEL 23 DE FEBRERO 2026 | Z2: Tiempo Ordinario Disponible | AA2: Horas asignadas | AF2: Saldo de Horas
V3: RH-F-24- Control de Horas Diarias
F4: 46076 | G4: - | V4: Rige: 16/03/2026 Versión:1 | Z4: =+V57 -> 0 | AA4: =-AF57 -> 0 | AF4: =+Z4+AA4 -> 0
B7: Nota: Llenar únicamente las celdas en color amarillo. | G7: Anote un 1 si la plaza está vacantes | H7: Según Acción de Personal | Q7: CALCULOS
B8: Nombre del funcionario con Acción de Personal | C8: Elija el puesto del funcionario | D8: Elija el Horario General | E8: Jornada | F8: Elija la Jornada | H8: Digite horas por Ausencias Injustifica-das | I8: Digite horas por Ausencias Justifica-das | J8: Digite horas por Permisos sin Goce de Salario | K8: Anote un 1 si está en Licencia por Maternidad o Paternidad | L8: Anote un 1 si está incapacitado por la CCSS, 3 primeros días | M8: Anote un 1 si está incapacita-do por la CCSS, del 4tp día en adelante | N8: Anote un 1 si está incapacitado por el INS | O8: Anote un 1 si está de Vacaciones | P8: Total de Horas | Q8: Día | R8: Tarde Noche | S8: Noche | T8: Total Horas | V8: Horas Ordinarias Disponibles convertidas a día | W8: Quién las laborará | X8: Elija el puesto del funcionario | Y8: Elija el Horario General | Z8: Elija el tipo de horas a Calcular | AA8: Digite las horas Aprobadas a Trabajar | AB8: Día | AC8: Tarde Noche | AD8: Noche | AE8: Total Horas Ordinarias convertidas a Dia | AF8: Total Horas Ordinarias convertidas a Dia
C9: 0 | D9: 0 | E9: =(IF(F9=Listas!$B$7,"8",IF(F9=Listas!$B$8,"7",IF(F9=Listas!$B$9,"6",IF(F9=Listas!$B$10,"7",IF(F9=Listas!$B$11,"6.125",IF(F9=Listas!$B$12,"5.250",IF(F9=Listas!$B$6,"0")))))))) -> 0 | F9: 0 | G9: 0 | H9: 0 | I9: 0 | J9: 0 | K9: 0 | L9: 0 | M9: 0 | N9: 0 | O9: 0 | P9: =+(G9*E9)+(H9+I9+J9)+(((K9+L9+O9)*E9/2))+(((M9+N9)*E9)) -> 0 | Q9: =IF(D9=Listas!$B$41,SUM(P9*1227)/1227,0) -> 0 | R9: =IF(D9=Listas!$B$42,SUM(P9*1403)/1227,0) -> 0 | S9: =IF(D9=Listas!$B$43,SUM(P9*1636)/1227,0) -> 0 | T9: =+Q9+R9+S9 -> 0 | U9: =IF(C9=Listas!$B$18,((T9*1227)*23%)+(T9*1227),IF(C9=Listas!$B$19,((T9*1227)*56%)+(T9*1227),IF(C9=Listas!$B$20,((T9*1227)*69%)+(T9*1227),IF(C9=Listas!$B$21,((T9*1227)*31%)+(T9*1227),IF(C9=Listas!$B$22,((T9*1227)*11%)+(T9*1227),IF(C9=Listas!$B$17,((T9*1227)*0%)+(T9*1227)))))))/1227.66 -> 0 | V9: =+U9 -> 0 | X9: 0 | Y9: 0 | Z9: 0 | AA9: 0 | AB9: =(IF(Y9=Listas!$B$41,SUM(IF(Z9=Listas!$B$27,SUM(AA9*1227),IF(Z9=Listas!$B$28,SUM(AA9*1841),IF(Z9=Listas!$B$29,SUM(AA9*2455)))))))/1227 -> 0 | AC9: =(IF(Y9=Listas!$B$42,SUM(IF(Z9=Listas!$B$27,SUM(AA9*1403),IF(Z9=Listas!$B$28,SUM(AA9*2104),IF(Z9=Listas!$B$29,SUM(AA9*2806)))))))/1227 -> 0 | AD9: =(IF(Y9=Listas!$B$43,SUM(IF(Z9=Listas!$B$27,SUM(AA9*1636),IF(Z9=Listas!$B$28,SUM(AA9*2454),IF(Z9=Listas!$B$29,SUM(AA9*3272)))))))/1227 -> 0 | AE9: =SUM(AB9:AD9) -> 0 | AF9: =(IF(X9=Listas!$B$18,+(AE9*23%)+(AE9),IF(X9=Listas!$B$19,+(AE9*56%)+(AE9),IF(X9=Listas!$B$20,+(AE9*103%)+(AE9),IF(X9=Listas!$B$21,+(AE9*31%)+(AE9),IF(X9=Listas!$B$22,+(AE9*11%)+(AE9),IF(X9=Listas!$B$17,+(AE9*0%)+(AE9),0))))))) -> 0
C10: 0 | D10: 0 | E10: =(IF(F10=Listas!$B$7,"8",IF(F10=Listas!$B$8,"7",IF(F10=Listas!$B$9,"6",IF(F10=Listas!$B$10,"7",IF(F10=Listas!$B$11,"6.125",IF(F10=Listas!$B$12,"5.250",IF(F10=Listas!$B$6,"0")))))))) -> 0 | F10: 0 | G10: 0 | H10: 0 | I10: 0 | J10: 0 | K10: 0 | L10: 0 | M10: 0 | N10: 0 | O10: 0 | P10: =+(G10*E10)+(H10+I10+J10)+(((K10+L10+O10)*E10/2))+(((M10+N10)*E10)) -> 0 | Q10: =IF(D10=Listas!$B$41,SUM(P10*1227)/1227,0) -> 0 | R10: =IF(D10=Listas!$B$42,SUM(P10*1403)/1227,0) -> 0 | S10: =IF(D10=Listas!$B$43,SUM(P10*1636)/1227,0) -> 0 | T10: =+Q10+R10+S10 -> 0 | U10: =IF(C10=Listas!$B$18,((T10*1227)*23%)+(T10*1227),IF(C10=Listas!$B$19,((T10*1227)*56%)+(T10*1227),IF(C10=Listas!$B$20,((T10*1227)*69%)+(T10*1227),IF(C10=Listas!$B$21,((T10*1227)*31%)+(T10*1227),IF(C10=Listas!$B$22,((T10*1227)*11%)+(T10*1227),IF(C10=Listas!$B$17,((T10*1227)*0%)+(T10*1227)))))))/1227.66 -> 0 | V10: =+U10 -> 0 | X10: 0 | Y10: 0 | Z10: 0 | AA10: 0 | AB10: =(IF(Y10=Listas!$B$41,SUM(IF(Z10=Listas!$B$27,SUM(AA10*1227),IF(Z10=Listas!$B$28,SUM(AA10*1841),IF(Z10=Listas!$B$29,SUM(AA10*2455)))))))/1227 -> 0 | AC10: =(IF(Y10=Listas!$B$42,SUM(IF(Z10=Listas!$B$27,SUM(AA10*1403),IF(Z10=Listas!$B$28,SUM(AA10*2104),IF(Z10=Listas!$B$29,SUM(AA10*2806)))))))/1227 -> 0 | AD10: =(IF(Y10=Listas!$B$43,SUM(IF(Z10=Listas!$B$27,SUM(AA10*1636),IF(Z10=Listas!$B$28,SUM(AA10*2454),IF(Z10=Listas!$B$29,SUM(AA10*3272)))))))/1227 -> 0 | AE10: =SUM(AB10:AD10) -> 0 | AF10: =(IF(X10=Listas!$B$18,+(AE10*23%)+(AE10),IF(X10=Listas!$B$19,+(AE10*56%)+(AE10),IF(X10=Listas!$B$20,+(AE10*103%)+(AE10),IF(X10=Listas!$B$21,+(AE10*31%)+(AE10),IF(X10=Listas!$B$22,+(AE10*11%)+(AE10),IF(X10=Listas!$B$17,+(AE10*0%)+(AE10),0))))))) -> 0
C11: 0 | D11: 0 | E11: =(IF(F11=Listas!$B$7,"8",IF(F11=Listas!$B$8,"7",IF(F11=Listas!$B$9,"6",IF(F11=Listas!$B$10,"7",IF(F11=Listas!$B$11,"6.125",IF(F11=Listas!$B$12,"5.250",IF(F11=Listas!$B$6,"0")))))))) -> 0 | F11: 0 | G11: 0 | H11: 0 | I11: 0 | J11: 0 | K11: 0 | L11: 0 | M11: 0 | N11: 0 | O11: 0 | P11: =+(G11*E11)+(H11+I11+J11)+(((K11+L11+O11)*E11/2))+(((M11+N11)*E11)) -> 0 | Q11: =IF(D11=Listas!$B$41,SUM(P11*1227)/1227,0) -> 0 | R11: =IF(D11=Listas!$B$42,SUM(P11*1403)/1227,0) -> 0 | S11: =IF(D11=Listas!$B$43,SUM(P11*1636)/1227,0) -> 0 | T11: =+Q11+R11+S11 -> 0 | U11: =IF(C11=Listas!$B$18,((T11*1227)*23%)+(T11*1227),IF(C11=Listas!$B$19,((T11*1227)*56%)+(T11*1227),IF(C11=Listas!$B$20,((T11*1227)*69%)+(T11*1227),IF(C11=Listas!$B$21,((T11*1227)*31%)+(T11*1227),IF(C11=Listas!$B$22,((T11*1227)*11%)+(T11*1227),IF(C11=Listas!$B$17,((T11*1227)*0%)+(T11*1227)))))))/1227.66 -> 0 | V11: =+U11 -> 0 | X11: 0 | Y11: 0 | Z11: 0 | AA11: 0 | AB11: =(IF(Y11=Listas!$B$41,SUM(IF(Z11=Listas!$B$27,SUM(AA11*1227),IF(Z11=Listas!$B$28,SUM(AA11*1841),IF(Z11=Listas!$B$29,SUM(AA11*2455)))))))/1227 -> 0 | AC11: =(IF(Y11=Listas!$B$42,SUM(IF(Z11=Listas!$B$27,SUM(AA11*1403),IF(Z11=Listas!$B$28,SUM(AA11*2104),IF(Z11=Listas!$B$29,SUM(AA11*2806)))))))/1227 -> 0 | AD11: =(IF(Y11=Listas!$B$43,SUM(IF(Z11=Listas!$B$27,SUM(AA11*1636),IF(Z11=Listas!$B$28,SUM(AA11*2454),IF(Z11=Listas!$B$29,SUM(AA11*3272)))))))/1227 -> 0 | AE11: =SUM(AB11:AD11) -> 0 | AF11: =(IF(X11=Listas!$B$18,+(AE11*23%)+(AE11),IF(X11=Listas!$B$19,+(AE11*56%)+(AE11),IF(X11=Listas!$B$20,+(AE11*103%)+(AE11),IF(X11=Listas!$B$21,+(AE11*31%)+(AE11),IF(X11=Listas!$B$22,+(AE11*11%)+(AE11),IF(X11=Listas!$B$17,+(AE11*0%)+(AE11),0))))))) -> 0
C12: 0 | D12: 0 | E12: =(IF(F12=Listas!$B$7,"8",IF(F12=Listas!$B$8,"7",IF(F12=Listas!$B$9,"6",IF(F12=Listas!$B$10,"7",IF(F12=Listas!$B$11,"6.125",IF(F12=Listas!$B$12,"5.250",IF(F12=Listas!$B$6,"0")))))))) -> 0 | F12: 0 | G12: 0 | H12: 0 | I12: 0 | J12: 0 | K12: 0 | L12: 0 | M12: 0 | N12: 0 | O12: 0 | P12: =+(G12*E12)+(H12+I12+J12)+(((K12+L12+O12)*E12/2))+(((M12+N12)*E12)) -> 0 | Q12: =IF(D12=Listas!$B$41,SUM(P12*1227)/1227,0) -> 0 | R12: =IF(D12=Listas!$B$42,SUM(P12*1403)/1227,0) -> 0 | S12: =IF(D12=Listas!$B$43,SUM(P12*1636)/1227,0) -> 0 | T12: =+Q12+R12+S12 -> 0 | U12: =IF(C12=Listas!$B$18,((T12*1227)*23%)+(T12*1227),IF(C12=Listas!$B$19,((T12*1227)*56%)+(T12*1227),IF(C12=Listas!$B$20,((T12*1227)*69%)+(T12*1227),IF(C12=Listas!$B$21,((T12*1227)*31%)+(T12*1227),IF(C12=Listas!$B$22,((T12*1227)*11%)+(T12*1227),IF(C12=Listas!$B$17,((T12*1227)*0%)+(T12*1227)))))))/1227.66 -> 0 | V12: =+U12 -> 0 | X12: 0 | Y12: 0 | Z12: 0 | AA12: 0 | AB12: =(IF(Y12=Listas!$B$41,SUM(IF(Z12=Listas!$B$27,SUM(AA12*1227),IF(Z12=Listas!$B$28,SUM(AA12*1841),IF(Z12=Listas!$B$29,SUM(AA12*2455)))))))/1227 -> 0 | AC12: =(IF(Y12=Listas!$B$42,SUM(IF(Z12=Listas!$B$27,SUM(AA12*1403),IF(Z12=Listas!$B$28,SUM(AA12*2104),IF(Z12=Listas!$B$29,SUM(AA12*2806)))))))/1227 -> 0 | AD12: =(IF(Y12=Listas!$B$43,SUM(IF(Z12=Listas!$B$27,SUM(AA12*1636),IF(Z12=Listas!$B$28,SUM(AA12*2454),IF(Z12=Listas!$B$29,SUM(AA12*3272)))))))/1227 -> 0 | AE12: =SUM(AB12:AD12) -> 0 | AF12: =(IF(X12=Listas!$B$18,+(AE12*23%)+(AE12),IF(X12=Listas!$B$19,+(AE12*56%)+(AE12),IF(X12=Listas!$B$20,+(AE12*103%)+(AE12),IF(X12=Listas!$B$21,+(AE12*31%)+(AE12),IF(X12=Listas!$B$22,+(AE12*11%)+(AE12),IF(X12=Listas!$B$17,+(AE12*0%)+(AE12),0))))))) -> 0
C13: 0 | D13: 0 | E13: =(IF(F13=Listas!$B$7,"8",IF(F13=Listas!$B$8,"7",IF(F13=Listas!$B$9,"6",IF(F13=Listas!$B$10,"7",IF(F13=Listas!$B$11,"6.125",IF(F13=Listas!$B$12,"5.250",IF(F13=Listas!$B$6,"0")))))))) -> 0 | F13: 0 | G13: 0 | H13: 0 | I13: 0 | J13: 0 | K13: 0 | L13: 0 | M13: 0 | N13: 0 | O13: 0 | P13: =+(G13*E13)+(H13+I13+J13)+(((K13+L13+O13)*E13/2))+(((M13+N13)*E13)) -> 0 | Q13: =IF(D13=Listas!$B$41,SUM(P13*1227)/1227,0) -> 0 | R13: =IF(D13=Listas!$B$42,SUM(P13*1403)/1227,0) -> 0 | S13: =IF(D13=Listas!$B$43,SUM(P13*1636)/1227,0) -> 0 | T13: =+Q13+R13+S13 -> 0 | U13: =IF(C13=Listas!$B$18,((T13*1227)*23%)+(T13*1227),IF(C13=Listas!$B$19,((T13*1227)*56%)+(T13*1227),IF(C13=Listas!$B$20,((T13*1227)*69%)+(T13*1227),IF(C13=Listas!$B$21,((T13*1227)*31%)+(T13*1227),IF(C13=Listas!$B$22,((T13*1227)*11%)+(T13*1227),IF(C13=Listas!$B$17,((T13*1227)*0%)+(T13*1227)))))))/1227.66 -> 0 | V13: =+U13 -> 0 | X13: 0 | Y13: 0 | Z13: 0 | AA13: 0 | AB13: =(IF(Y13=Listas!$B$41,SUM(IF(Z13=Listas!$B$27,SUM(AA13*1227),IF(Z13=Listas!$B$28,SUM(AA13*1841),IF(Z13=Listas!$B$29,SUM(AA13*2455)))))))/1227 -> 0 | AC13: =(IF(Y13=Listas!$B$42,SUM(IF(Z13=Listas!$B$27,SUM(AA13*1403),IF(Z13=Listas!$B$28,SUM(AA13*2104),IF(Z13=Listas!$B$29,SUM(AA13*2806)))))))/1227 -> 0 | AD13: =(IF(Y13=Listas!$B$43,SUM(IF(Z13=Listas!$B$27,SUM(AA13*1636),IF(Z13=Listas!$B$28,SUM(AA13*2454),IF(Z13=Listas!$B$29,SUM(AA13*3272)))))))/1227 -> 0 | AE13: =SUM(AB13:AD13) -> 0 | AF13: =(IF(X13=Listas!$B$18,+(AE13*23%)+(AE13),IF(X13=Listas!$B$19,+(AE13*56%)+(AE13),IF(X13=Listas!$B$20,+(AE13*103%)+(AE13),IF(X13=Listas!$B$21,+(AE13*31%)+(AE13),IF(X13=Listas!$B$22,+(AE13*11%)+(AE13),IF(X13=Listas!$B$17,+(AE13*0%)+(AE13),0))))))) -> 0
C14: 0 | D14: 0 | E14: =(IF(F14=Listas!$B$7,"8",IF(F14=Listas!$B$8,"7",IF(F14=Listas!$B$9,"6",IF(F14=Listas!$B$10,"7",IF(F14=Listas!$B$11,"6.125",IF(F14=Listas!$B$12,"5.250",IF(F14=Listas!$B$6,"0")))))))) -> 0 | F14: 0 | G14: 0 | H14: 0 | I14: 0 | J14: 0 | K14: 0 | L14: 0 | M14: 0 | N14: 0 | O14: 0 | P14: =+(G14*E14)+(H14+I14+J14)+(((K14+L14+O14)*E14/2))+(((M14+N14)*E14)) -> 0 | Q14: =IF(D14=Listas!$B$41,SUM(P14*1227)/1227,0) -> 0 | R14: =IF(D14=Listas!$B$42,SUM(P14*1403)/1227,0) -> 0 | S14: =IF(D14=Listas!$B$43,SUM(P14*1636)/1227,0) -> 0 | T14: =+Q14+R14+S14 -> 0 | U14: =IF(C14=Listas!$B$18,((T14*1227)*23%)+(T14*1227),IF(C14=Listas!$B$19,((T14*1227)*56%)+(T14*1227),IF(C14=Listas!$B$20,((T14*1227)*69%)+(T14*1227),IF(C14=Listas!$B$21,((T14*1227)*31%)+(T14*1227),IF(C14=Listas!$B$22,((T14*1227)*11%)+(T14*1227),IF(C14=Listas!$B$17,((T14*1227)*0%)+(T14*1227)))))))/1227.66 -> 0 | V14: =+U14 -> 0 | X14: 0 | Y14: 0 | Z14: 0 | AA14: 0 | AB14: =(IF(Y14=Listas!$B$41,SUM(IF(Z14=Listas!$B$27,SUM(AA14*1227),IF(Z14=Listas!$B$28,SUM(AA14*1841),IF(Z14=Listas!$B$29,SUM(AA14*2455)))))))/1227 -> 0 | AC14: =(IF(Y14=Listas!$B$42,SUM(IF(Z14=Listas!$B$27,SUM(AA14*1403),IF(Z14=Listas!$B$28,SUM(AA14*2104),IF(Z14=Listas!$B$29,SUM(AA14*2806)))))))/1227 -> 0 | AD14: =(IF(Y14=Listas!$B$43,SUM(IF(Z14=Listas!$B$27,SUM(AA14*1636),IF(Z14=Listas!$B$28,SUM(AA14*2454),IF(Z14=Listas!$B$29,SUM(AA14*3272)))))))/1227 -> 0 | AE14: =SUM(AB14:AD14) -> 0 | AF14: =(IF(X14=Listas!$B$18,+(AE14*23%)+(AE14),IF(X14=Listas!$B$19,+(AE14*56%)+(AE14),IF(X14=Listas!$B$20,+(AE14*103%)+(AE14),IF(X14=Listas!$B$21,+(AE14*31%)+(AE14),IF(X14=Listas!$B$22,+(AE14*11%)+(AE14),IF(X14=Listas!$B$17,+(AE14*0%)+(AE14),0))))))) -> 0
C15: 0 | D15: 0 | E15: =(IF(F15=Listas!$B$7,"8",IF(F15=Listas!$B$8,"7",IF(F15=Listas!$B$9,"6",IF(F15=Listas!$B$10,"7",IF(F15=Listas!$B$11,"6.125",IF(F15=Listas!$B$12,"5.250",IF(F15=Listas!$B$6,"0")))))))) -> 0 | F15: 0 | G15: 0 | H15: 0 | I15: 0 | J15: 0 | K15: 0 | L15: 0 | M15: 0 | N15: 0 | O15: 0 | P15: =+(G15*E15)+(H15+I15+J15)+(((K15+L15+O15)*E15/2))+(((M15+N15)*E15)) -> 0 | Q15: =IF(D15=Listas!$B$41,SUM(P15*1227)/1227,0) -> 0 | R15: =IF(D15=Listas!$B$42,SUM(P15*1403)/1227,0) -> 0 | S15: =IF(D15=Listas!$B$43,SUM(P15*1636)/1227,0) -> 0 | T15: =+Q15+R15+S15 -> 0 | U15: =IF(C15=Listas!$B$18,((T15*1227)*23%)+(T15*1227),IF(C15=Listas!$B$19,((T15*1227)*56%)+(T15*1227),IF(C15=Listas!$B$20,((T15*1227)*69%)+(T15*1227),IF(C15=Listas!$B$21,((T15*1227)*31%)+(T15*1227),IF(C15=Listas!$B$22,((T15*1227)*11%)+(T15*1227),IF(C15=Listas!$B$17,((T15*1227)*0%)+(T15*1227)))))))/1227.66 -> 0 | V15: =+U15 -> 0 | X15: 0 | Y15: 0 | Z15: 0 | AA15: 0 | AB15: =(IF(Y15=Listas!$B$41,SUM(IF(Z15=Listas!$B$27,SUM(AA15*1227),IF(Z15=Listas!$B$28,SUM(AA15*1841),IF(Z15=Listas!$B$29,SUM(AA15*2455)))))))/1227 -> 0 | AC15: =(IF(Y15=Listas!$B$42,SUM(IF(Z15=Listas!$B$27,SUM(AA15*1403),IF(Z15=Listas!$B$28,SUM(AA15*2104),IF(Z15=Listas!$B$29,SUM(AA15*2806)))))))/1227 -> 0 | AD15: =(IF(Y15=Listas!$B$43,SUM(IF(Z15=Listas!$B$27,SUM(AA15*1636),IF(Z15=Listas!$B$28,SUM(AA15*2454),IF(Z15=Listas!$B$29,SUM(AA15*3272)))))))/1227 -> 0 | AE15: =SUM(AB15:AD15) -> 0 | AF15: =(IF(X15=Listas!$B$18,+(AE15*23%)+(AE15),IF(X15=Listas!$B$19,+(AE15*56%)+(AE15),IF(X15=Listas!$B$20,+(AE15*103%)+(AE15),IF(X15=Listas!$B$21,+(AE15*31%)+(AE15),IF(X15=Listas!$B$22,+(AE15*11%)+(AE15),IF(X15=Listas!$B$17,+(AE15*0%)+(AE15),0))))))) -> 0
C16: 0 | D16: 0 | E16: =(IF(F16=Listas!$B$7,"8",IF(F16=Listas!$B$8,"7",IF(F16=Listas!$B$9,"6",IF(F16=Listas!$B$10,"7",IF(F16=Listas!$B$11,"6.125",IF(F16=Listas!$B$12,"5.250",IF(F16=Listas!$B$6,"0")))))))) -> 0 | F16: 0 | G16: 0 | H16: 0 | I16: 0 | J16: 0 | K16: 0 | L16: 0 | M16: 0 | N16: 0 | O16: 0 | P16: =+(G16*E16)+(H16+I16+J16)+(((K16+L16+O16)*E16/2))+(((M16+N16)*E16)) -> 0 | Q16: =IF(D16=Listas!$B$41,SUM(P16*1227)/1227,0) -> 0 | R16: =IF(D16=Listas!$B$42,SUM(P16*1403)/1227,0) -> 0 | S16: =IF(D16=Listas!$B$43,SUM(P16*1636)/1227,0) -> 0 | T16: =+Q16+R16+S16 -> 0 | U16: =IF(C16=Listas!$B$18,((T16*1227)*23%)+(T16*1227),IF(C16=Listas!$B$19,((T16*1227)*56%)+(T16*1227),IF(C16=Listas!$B$20,((T16*1227)*69%)+(T16*1227),IF(C16=Listas!$B$21,((T16*1227)*31%)+(T16*1227),IF(C16=Listas!$B$22,((T16*1227)*11%)+(T16*1227),IF(C16=Listas!$B$17,((T16*1227)*0%)+(T16*1227)))))))/1227.66 -> 0 | V16: =+U16 -> 0 | X16: 0 | Y16: 0 | Z16: 0 | AA16: 0 | AB16: =(IF(Y16=Listas!$B$41,SUM(IF(Z16=Listas!$B$27,SUM(AA16*1227),IF(Z16=Listas!$B$28,SUM(AA16*1841),IF(Z16=Listas!$B$29,SUM(AA16*2455)))))))/1227 -> 0 | AC16: =(IF(Y16=Listas!$B$42,SUM(IF(Z16=Listas!$B$27,SUM(AA16*1403),IF(Z16=Listas!$B$28,SUM(AA16*2104),IF(Z16=Listas!$B$29,SUM(AA16*2806)))))))/1227 -> 0 | AD16: =(IF(Y16=Listas!$B$43,SUM(IF(Z16=Listas!$B$27,SUM(AA16*1636),IF(Z16=Listas!$B$28,SUM(AA16*2454),IF(Z16=Listas!$B$29,SUM(AA16*3272)))))))/1227 -> 0 | AE16: =SUM(AB16:AD16) -> 0 | AF16: =(IF(X16=Listas!$B$18,+(AE16*23%)+(AE16),IF(X16=Listas!$B$19,+(AE16*56%)+(AE16),IF(X16=Listas!$B$20,+(AE16*103%)+(AE16),IF(X16=Listas!$B$21,+(AE16*31%)+(AE16),IF(X16=Listas!$B$22,+(AE16*11%)+(AE16),IF(X16=Listas!$B$17,+(AE16*0%)+(AE16),0))))))) -> 0
C17: 0 | D17: 0 | E17: =(IF(F17=Listas!$B$7,"8",IF(F17=Listas!$B$8,"7",IF(F17=Listas!$B$9,"6",IF(F17=Listas!$B$10,"7",IF(F17=Listas!$B$11,"6.125",IF(F17=Listas!$B$12,"5.250",IF(F17=Listas!$B$6,"0")))))))) -> 0 | F17: 0 | G17: 0 | H17: 0 | I17: 0 | J17: 0 | K17: 0 | L17: 0 | M17: 0 | N17: 0 | O17: 0 | P17: =+(G17*E17)+(H17+I17+J17)+(((K17+L17+O17)*E17/2))+(((M17+N17)*E17)) -> 0 | Q17: =IF(D17=Listas!$B$41,SUM(P17*1227)/1227,0) -> 0 | R17: =IF(D17=Listas!$B$42,SUM(P17*1403)/1227,0) -> 0 | S17: =IF(D17=Listas!$B$43,SUM(P17*1636)/1227,0) -> 0 | T17: =+Q17+R17+S17 -> 0 | U17: =IF(C17=Listas!$B$18,((T17*1227)*23%)+(T17*1227),IF(C17=Listas!$B$19,((T17*1227)*56%)+(T17*1227),IF(C17=Listas!$B$20,((T17*1227)*69%)+(T17*1227),IF(C17=Listas!$B$21,((T17*1227)*31%)+(T17*1227),IF(C17=Listas!$B$22,((T17*1227)*11%)+(T17*1227),IF(C17=Listas!$B$17,((T17*1227)*0%)+(T17*1227)))))))/1227.66 -> 0 | V17: =+U17 -> 0 | X17: 0 | Y17: 0 | Z17: 0 | AA17: 0 | AB17: =(IF(Y17=Listas!$B$41,SUM(IF(Z17=Listas!$B$27,SUM(AA17*1227),IF(Z17=Listas!$B$28,SUM(AA17*1841),IF(Z17=Listas!$B$29,SUM(AA17*2455)))))))/1227 -> 0 | AC17: =(IF(Y17=Listas!$B$42,SUM(IF(Z17=Listas!$B$27,SUM(AA17*1403),IF(Z17=Listas!$B$28,SUM(AA17*2104),IF(Z17=Listas!$B$29,SUM(AA17*2806)))))))/1227 -> 0 | AD17: =(IF(Y17=Listas!$B$43,SUM(IF(Z17=Listas!$B$27,SUM(AA17*1636),IF(Z17=Listas!$B$28,SUM(AA17*2454),IF(Z17=Listas!$B$29,SUM(AA17*3272)))))))/1227 -> 0 | AE17: =SUM(AB17:AD17) -> 0 | AF17: =(IF(X17=Listas!$B$18,+(AE17*23%)+(AE17),IF(X17=Listas!$B$19,+(AE17*56%)+(AE17),IF(X17=Listas!$B$20,+(AE17*103%)+(AE17),IF(X17=Listas!$B$21,+(AE17*31%)+(AE17),IF(X17=Listas!$B$22,+(AE17*11%)+(AE17),IF(X17=Listas!$B$17,+(AE17*0%)+(AE17),0))))))) -> 0
C18: 0 | D18: 0 | E18: =(IF(F18=Listas!$B$7,"8",IF(F18=Listas!$B$8,"7",IF(F18=Listas!$B$9,"6",IF(F18=Listas!$B$10,"7",IF(F18=Listas!$B$11,"6.125",IF(F18=Listas!$B$12,"5.250",IF(F18=Listas!$B$6,"0")))))))) -> 0 | F18: 0 | G18: 0 | H18: 0 | I18: 0 | J18: 0 | K18: 0 | L18: 0 | M18: 0 | N18: 0 | O18: 0 | P18: =+(G18*E18)+(H18+I18+J18)+(((K18+L18+O18)*E18/2))+(((M18+N18)*E18)) -> 0 | Q18: =IF(D18=Listas!$B$41,SUM(P18*1227)/1227,0) -> 0 | R18: =IF(D18=Listas!$B$42,SUM(P18*1403)/1227,0) -> 0 | S18: =IF(D18=Listas!$B$43,SUM(P18*1636)/1227,0) -> 0 | T18: =+Q18+R18+S18 -> 0 | U18: =IF(C18=Listas!$B$18,((T18*1227)*23%)+(T18*1227),IF(C18=Listas!$B$19,((T18*1227)*56%)+(T18*1227),IF(C18=Listas!$B$20,((T18*1227)*69%)+(T18*1227),IF(C18=Listas!$B$21,((T18*1227)*31%)+(T18*1227),IF(C18=Listas!$B$22,((T18*1227)*11%)+(T18*1227),IF(C18=Listas!$B$17,((T18*1227)*0%)+(T18*1227)))))))/1227.66 -> 0 | V18: =+U18 -> 0 | X18: 0 | Y18: 0 | Z18: 0 | AA18: 0 | AB18: =(IF(Y18=Listas!$B$41,SUM(IF(Z18=Listas!$B$27,SUM(AA18*1227),IF(Z18=Listas!$B$28,SUM(AA18*1841),IF(Z18=Listas!$B$29,SUM(AA18*2455)))))))/1227 -> 0 | AC18: =(IF(Y18=Listas!$B$42,SUM(IF(Z18=Listas!$B$27,SUM(AA18*1403),IF(Z18=Listas!$B$28,SUM(AA18*2104),IF(Z18=Listas!$B$29,SUM(AA18*2806)))))))/1227 -> 0 | AD18: =(IF(Y18=Listas!$B$43,SUM(IF(Z18=Listas!$B$27,SUM(AA18*1636),IF(Z18=Listas!$B$28,SUM(AA18*2454),IF(Z18=Listas!$B$29,SUM(AA18*3272)))))))/1227 -> 0 | AE18: =SUM(AB18:AD18) -> 0 | AF18: =(IF(X18=Listas!$B$18,+(AE18*23%)+(AE18),IF(X18=Listas!$B$19,+(AE18*56%)+(AE18),IF(X18=Listas!$B$20,+(AE18*103%)+(AE18),IF(X18=Listas!$B$21,+(AE18*31%)+(AE18),IF(X18=Listas!$B$22,+(AE18*11%)+(AE18),IF(X18=Listas!$B$17,+(AE18*0%)+(AE18),0))))))) -> 0
C19: 0 | D19: 0 | E19: =(IF(F19=Listas!$B$7,"8",IF(F19=Listas!$B$8,"7",IF(F19=Listas!$B$9,"6",IF(F19=Listas!$B$10,"7",IF(F19=Listas!$B$11,"6.125",IF(F19=Listas!$B$12,"5.250",IF(F19=Listas!$B$6,"0")))))))) -> 0 | F19: 0 | G19: 0 | H19: 0 | I19: 0 | J19: 0 | K19: 0 | L19: 0 | M19: 0 | N19: 0 | O19: 0 | P19: =+(G19*E19)+(H19+I19+J19)+(((K19+L19+O19)*E19/2))+(((M19+N19)*E19)) -> 0 | Q19: =IF(D19=Listas!$B$41,SUM(P19*1227)/1227,0) -> 0 | R19: =IF(D19=Listas!$B$42,SUM(P19*1403)/1227,0) -> 0 | S19: =IF(D19=Listas!$B$43,SUM(P19*1636)/1227,0) -> 0 | T19: =+Q19+R19+S19 -> 0 | U19: =IF(C19=Listas!$B$18,((T19*1227)*23%)+(T19*1227),IF(C19=Listas!$B$19,((T19*1227)*56%)+(T19*1227),IF(C19=Listas!$B$20,((T19*1227)*69%)+(T19*1227),IF(C19=Listas!$B$21,((T19*1227)*31%)+(T19*1227),IF(C19=Listas!$B$22,((T19*1227)*11%)+(T19*1227),IF(C19=Listas!$B$17,((T19*1227)*0%)+(T19*1227)))))))/1227.66 -> 0 | V19: =+U19 -> 0 | X19: 0 | Y19: 0 | Z19: 0 | AA19: 0 | AB19: =(IF(Y19=Listas!$B$41,SUM(IF(Z19=Listas!$B$27,SUM(AA19*1227),IF(Z19=Listas!$B$28,SUM(AA19*1841),IF(Z19=Listas!$B$29,SUM(AA19*2455)))))))/1227 -> 0 | AC19: =(IF(Y19=Listas!$B$42,SUM(IF(Z19=Listas!$B$27,SUM(AA19*1403),IF(Z19=Listas!$B$28,SUM(AA19*2104),IF(Z19=Listas!$B$29,SUM(AA19*2806)))))))/1227 -> 0 | AD19: =(IF(Y19=Listas!$B$43,SUM(IF(Z19=Listas!$B$27,SUM(AA19*1636),IF(Z19=Listas!$B$28,SUM(AA19*2454),IF(Z19=Listas!$B$29,SUM(AA19*3272)))))))/1227 -> 0 | AE19: =SUM(AB19:AD19) -> 0 | AF19: =(IF(X19=Listas!$B$18,+(AE19*23%)+(AE19),IF(X19=Listas!$B$19,+(AE19*56%)+(AE19),IF(X19=Listas!$B$20,+(AE19*103%)+(AE19),IF(X19=Listas!$B$21,+(AE19*31%)+(AE19),IF(X19=Listas!$B$22,+(AE19*11%)+(AE19),IF(X19=Listas!$B$17,+(AE19*0%)+(AE19),0))))))) -> 0
C20: 0 | D20: 0 | E20: =(IF(F20=Listas!$B$7,"8",IF(F20=Listas!$B$8,"7",IF(F20=Listas!$B$9,"6",IF(F20=Listas!$B$10,"7",IF(F20=Listas!$B$11,"6.125",IF(F20=Listas!$B$12,"5.250",IF(F20=Listas!$B$6,"0")))))))) -> 0 | F20: 0 | G20: 0 | H20: 0 | I20: 0 | J20: 0 | K20: 0 | L20: 0 | M20: 0 | N20: 0 | O20: 0 | P20: =+(G20*E20)+(H20+I20+J20)+(((K20+L20+O20)*E20/2))+(((M20+N20)*E20)) -> 0 | Q20: =IF(D20=Listas!$B$41,SUM(P20*1227)/1227,0) -> 0 | R20: =IF(D20=Listas!$B$42,SUM(P20*1403)/1227,0) -> 0 | S20: =IF(D20=Listas!$B$43,SUM(P20*1636)/1227,0) -> 0 | T20: =+Q20+R20+S20 -> 0 | U20: =IF(C20=Listas!$B$18,((T20*1227)*23%)+(T20*1227),IF(C20=Listas!$B$19,((T20*1227)*56%)+(T20*1227),IF(C20=Listas!$B$20,((T20*1227)*69%)+(T20*1227),IF(C20=Listas!$B$21,((T20*1227)*31%)+(T20*1227),IF(C20=Listas!$B$22,((T20*1227)*11%)+(T20*1227),IF(C20=Listas!$B$17,((T20*1227)*0%)+(T20*1227)))))))/1227.66 -> 0 | V20: =+U20 -> 0 | X20: 0 | Y20: 0 | Z20: 0 | AA20: 0 | AB20: =(IF(Y20=Listas!$B$41,SUM(IF(Z20=Listas!$B$27,SUM(AA20*1227),IF(Z20=Listas!$B$28,SUM(AA20*1841),IF(Z20=Listas!$B$29,SUM(AA20*2455)))))))/1227 -> 0 | AC20: =(IF(Y20=Listas!$B$42,SUM(IF(Z20=Listas!$B$27,SUM(AA20*1403),IF(Z20=Listas!$B$28,SUM(AA20*2104),IF(Z20=Listas!$B$29,SUM(AA20*2806)))))))/1227 -> 0 | AD20: =(IF(Y20=Listas!$B$43,SUM(IF(Z20=Listas!$B$27,SUM(AA20*1636),IF(Z20=Listas!$B$28,SUM(AA20*2454),IF(Z20=Listas!$B$29,SUM(AA20*3272)))))))/1227 -> 0 | AE20: =SUM(AB20:AD20) -> 0 | AF20: =(IF(X20=Listas!$B$18,+(AE20*23%)+(AE20),IF(X20=Listas!$B$19,+(AE20*56%)+(AE20),IF(X20=Listas!$B$20,+(AE20*103%)+(AE20),IF(X20=Listas!$B$21,+(AE20*31%)+(AE20),IF(X20=Listas!$B$22,+(AE20*11%)+(AE20),IF(X20=Listas!$B$17,+(AE20*0%)+(AE20),0))))))) -> 0
... C56: 0 | D56: 0 | E56: =(IF(F56=Listas!$B$7,"8",IF(F56=Listas!$B$8,"7",IF(F56=Listas!$B$9,"6",IF(F56=Listas!$B$10,"7",IF(F56=Listas!$B$11,"6.125",IF(F56=Listas!$B$12,"5.250",IF(F56=Listas!$B$6,"0")))))))) -> 0 | F56: 0 | G56: 0 | H56: 0 | I56: 0 | J56: 0 | K56: 0 | L56: 0 | M56: 0 | N56: 0 | O56: 0 | P56: =+(G56*E56)+(H56+I56+J56)+(((K56+L56+O56)*E56/2))+(((M56+N56)*E56)) -> 0 | Q56: =IF(D56=Listas!$B$41,SUM(P56*1227)/1227,0) -> 0 | R56: =IF(D56=Listas!$B$42,SUM(P56*1403)/1227,0) -> 0 | S56: =IF(D56=Listas!$B$43,SUM(P56*1636)/1227,0) -> 0 | T56: =+Q56+R56+S56 -> 0 | U56: =IF(C56=Listas!$B$18,((T56*1227)*23%)+(T56*1227),IF(C56=Listas!$B$19,((T56*1227)*56%)+(T56*1227),IF(C56=Listas!$B$20,((T56*1227)*69%)+(T56*1227),IF(C56=Listas!$B$21,((T56*1227)*31%)+(T56*1227),IF(C56=Listas!$B$22,((T56*1227)*11%)+(T56*1227),IF(C56=Listas!$B$17,((T56*1227)*0%)+(T56*1227)))))))/1227.66 -> 0 | V56: =+U56 -> 0 | X56: 0 | Y56: 0 | Z56: 0 | AA56: 0 | AB56: =(IF(Y56=Listas!$B$41,SUM(IF(Z56=Listas!$B$27,SUM(AA56*1227),IF(Z56=Listas!$B$28,SUM(AA56*1841),IF(Z56=Listas!$B$29,SUM(AA56*2455)))))))/1227 -> 0 | AC56: =(IF(Y56=Listas!$B$42,SUM(IF(Z56=Listas!$B$27,SUM(AA56*1403),IF(Z56=Listas!$B$28,SUM(AA56*2104),IF(Z56=Listas!$B$29,SUM(AA56*2806)))))))/1227 -> 0 | AD56: =(IF(Y56=Listas!$B$43,SUM(IF(Z56=Listas!$B$27,SUM(AA56*1636),IF(Z56=Listas!$B$28,SUM(AA56*2454),IF(Z56=Listas!$B$29,SUM(AA56*3272)))))))/1227 -> 0 | AE56: =SUM(AB56:AD56) -> 0 | AF56: =(IF(X56=Listas!$B$18,+(AE56*23%)+(AE56),IF(X56=Listas!$B$19,+(AE56*56%)+(AE56),IF(X56=Listas!$B$20,+(AE56*103%)+(AE56),IF(X56=Listas!$B$21,+(AE56*31%)+(AE56),IF(X56=Listas!$B$22,+(AE56*11%)+(AE56),IF(X56=Listas!$B$17,+(AE56*0%)+(AE56),0))))))) -> 0
B57: TOTALES | G57: =SUM(G9:G56) -> 0 | H57: =SUM(H9:H56) -> 0 | I57: =SUM(I9:I56) -> 0 | J57: =SUM(J9:J56) -> 0 | K57: =SUM(K9:K56) -> 0 | L57: =SUM(L9:L56) -> 0 | M57: =SUM(M9:M56) -> 0 | N57: =SUM(N9:N56) -> 0 | ... W57: =SUM(W9:W56) -> 0 | AA57: =SUM(AA9:AA56) -> 0 | AB57: =SUM(AB9:AB56) -> 0 | AC57: =SUM(AC9:AC56) -> 0 | AD57: =SUM(AD9:AD56) -> 0 | AE57: =SUM(AE9:AE56) -> 0 | AF57: =SUM(AF9:AF56) -> 0

Sheet 2
F2: FECHA | G2: PROYECTO | V2: =+'1'!$V$2 -> RIGE A PARTIR DEL 23 DE FEBRERO 2026 | Z2: Tiempo Ordinario Disponible | AA2: Horas asignadas | AF2: Saldo de Horas
V3: =+'1'!$V$3 -> RH-F-24- Control de Horas Diarias
F4: =+'1'!F4+1 -> 46077 | G4: =+'1'!$G$4 -> - | V4: =+'1'!$V$4 -> Rige: 16/03/2026 Versión:1 | Z4: =+V57 -> 0 | AA4: =-AF57 -> 0 | AF4: =+Z4+AA4+'1'!AF4 -> 0
B7: Nota: Llenar únicamente las celdas en color amarillo. | G7: Anote un 1 si la plaza está vacantes | H7: Según Acción de Personal | Q7: CALCULOS
B8: Nombre del funcionario con Acción de Personal | C8: Elija el puesto del funcionario | D8: Elija el Horario General | E8: Jornada | F8: Elija la Jornada | H8: Digite horas por Ausencias Injustifica-das | I8: Digite horas por Ausencias Justifica-das | J8: Digite horas por Permisos sin Goce de Salario | K8: Anote un 1 si está en Licencia por Maternidad o Paternidad | L8: Anote un 1 si está incapacitado por la CCSS, 3 primeros días | M8: Anote un 1 si está incapacita-do por la CCSS, del 4tp día en adelante | N8: Anote un 1 si está incapacitado por el INS | O8: Anote un 1 si está de Vacaciones | P8: Total de Horas | Q8: Día | R8: Tarde Noche | S8: Noche | T8: Total Horas | V8: Horas Ordinarias Disponibles convertidas a día | W8: Quién las laborará | X8: Elija el puesto del funcionario | Y8: Elija el Horario General | Z8: Elija el tipo de horas a Calcular | AA8: Digite las horas Aprobadas a Trabajar | AB8: Día | AC8: Tarde Noche | AD8: Noche | AE8: Total Horas Ordinarias convertidas a Dia | AF8: Total Horas Ordinarias convertidas a Dia
C9: 0 | D9: 0 | E9: =(IF(F9=Listas!$B$7,"8",IF(F9=Listas!$B$8,"7",IF(F9=Listas!$B$9,"6",IF(F9=Listas!$B$10,"7",IF(F9=Listas!$B$11,"6.125",IF(F9=Listas!$B$12,"5.250",IF(F9=Listas!$B$6,"0")))))))) -> 0 | F9: 0 | G9: 0 | H9: 0 | I9: 0 | J9: 0 | K9: 0 | L9: 0 | M9: 0 | N9: 0 | O9: 0 | P9: =+(G9*E9)+(H9+I9+J9)+(((K9+L9+O9)*E9/2))+(((M9+N9)*E9)) -> 0 | Q9: =IF(D9=Listas!$B$41,SUM(P9*1227)/1227,0) -> 0 | R9: =IF(D9=Listas!$B$42,SUM(P9*1403)/1227,0) -> 0 | S9: =IF(D9=Listas!$B$43,SUM(P9*1636)/1227,0) -> 0 | T9: =+Q9+R9+S9 -> 0 | U9: =IF(C9=Listas!$B$18,((T9*1227)*23%)+(T9*1227),IF(C9=Listas!$B$19,((T9*1227)*56%)+(T9*1227),IF(C9=Listas!$B$20,((T9*1227)*69%)+(T9*1227),IF(C9=Listas!$B$21,((T9*1227)*31%)+(T9*1227),IF(C9=Listas!$B$22,((T9*1227)*11%)+(T9*1227),IF(C9=Listas!$B$17,((T9*1227)*0%)+(T9*1227)))))))/1227.66 -> 0 | V9: =+U9 -> 0 | X9: 0 | Y9: 0 | Z9: 0 | AA9: 0 | AB9: =(IF(Y9=Listas!$B$41,SUM(IF(Z9=Listas!$B$27,SUM(AA9*1227),IF(Z9=Listas!$B$28,SUM(AA9*1841),IF(Z9=Listas!$B$29,SUM(AA9*2455)))))))/1227 -> 0 | AC9: =(IF(Y9=Listas!$B$42,SUM(IF(Z9=Listas!$B$27,SUM(AA9*1403),IF(Z9=Listas!$B$28,SUM(AA9*2104),IF(Z9=Listas!$B$29,SUM(AA9*2806)))))))/1227 -> 0 | AD9: =(IF(Y9=Listas!$B$43,SUM(IF(Z9=Listas!$B$27,SUM(AA9*1636),IF(Z9=Listas!$B$28,SUM(AA9*2454),IF(Z9=Listas!$B$29,SUM(AA9*3272)))))))/1227 -> 0 | AE9: =SUM(AB9:AD9) -> 0 | AF9: =(IF(X9=Listas!$B$18,+(AE9*23%)+(AE9),IF(X9=Listas!$B$19,+(AE9*56%)+(AE9),IF(X9=Listas!$B$20,+(AE9*103%)+(AE9),IF(X9=Listas!$B$21,+(AE9*31%)+(AE9),IF(X9=Listas!$B$22,+(AE9*11%)+(AE9),IF(X9=Listas!$B$17,+(AE9*0%)+(AE9),0))))))) -> 0
C10: 0 | D10: 0 | E10: =(IF(F10=Listas!$B$7,"8",IF(F10=Listas!$B$8,"7",IF(F10=Listas!$B$9,"6",IF(F10=Listas!$B$10,"7",IF(F10=Listas!$B$11,"6.125",IF(F10=Listas!$B$12,"5.250",IF(F10=Listas!$B$6,"0")))))))) -> 0 | F10: 0 | G10: 0 | H10: 0 | I10: 0 | J10: 0 | K10: 0 | L10: 0 | M10: 0 | N10: 0 | O10: 0 | P10: =+(G10*E10)+(H10+I10+J10)+(((K10+L10+O10)*E10/2))+(((M10+N10)*E10)) -> 0 | Q10: =IF(D10=Listas!$B$41,SUM(P10*1227)/1227,0) -> 0 | R10: =IF(D10=Listas!$B$42,SUM(P10*1403)/1227,0) -> 0 | S10: =IF(D10=Listas!$B$43,SUM(P10*1636)/1227,0) -> 0 | T10: =+Q10+R10+S10 -> 0 | U10: =IF(C10=Listas!$B$18,((T10*1227)*23%)+(T10*1227),IF(C10=Listas!$B$19,((T10*1227)*56%)+(T10*1227),IF(C10=Listas!$B$20,((T10*1227)*69%)+(T10*1227),IF(C10=Listas!$B$21,((T10*1227)*31%)+(T10*1227),IF(C10=Listas!$B$22,((T10*1227)*11%)+(T10*1227),IF(C10=Listas!$B$17,((T10*1227)*0%)+(T10*1227)))))))/1227.66 -> 0 | V10: =+U10 -> 0 | X10: 0 | Y10: 0 | Z10: 0 | AA10: 0 | AB10: =(IF(Y10=Listas!$B$41,SUM(IF(Z10=Listas!$B$27,SUM(AA10*1227),IF(Z10=Listas!$B$28,SUM(AA10*1841),IF(Z10=Listas!$B$29,SUM(AA10*2455)))))))/1227 -> 0 | AC10: =(IF(Y10=Listas!$B$42,SUM(IF(Z10=Listas!$B$27,SUM(AA10*1403),IF(Z10=Listas!$B$28,SUM(AA10*2104),IF(Z10=Listas!$B$29,SUM(AA10*2806)))))))/1227 -> 0 | AD10: =(IF(Y10=Listas!$B$43,SUM(IF(Z10=Listas!$B$27,SUM(AA10*1636),IF(Z10=Listas!$B$28,SUM(AA10*2454),IF(Z10=Listas!$B$29,SUM(AA10*3272)))))))/1227 -> 0 | AE10: =SUM(AB10:AD10) -> 0 | AF10: =(IF(X10=Listas!$B$18,+(AE10*23%)+(AE10),IF(X10=Listas!$B$19,+(AE10*56%)+(AE10),IF(X10=Listas!$B$20,+(AE10*103%)+(AE10),IF(X10=Listas!$B$21,+(AE10*31%)+(AE10),IF(X10=Listas!$B$22,+(AE10*11%)+(AE10),IF(X10=Listas!$B$17,+(AE10*0%)+(AE10),0))))))) -> 0
C11: 0 | D11: 0 | E11: =(IF(F11=Listas!$B$7,"8",IF(F11=Listas!$B$8,"7",IF(F11=Listas!$B$9,"6",IF(F11=Listas!$B$10,"7",IF(F11=Listas!$B$11,"6.125",IF(F11=Listas!$B$12,"5.250",IF(F11=Listas!$B$6,"0")))))))) -> 0 | F11: 0 | G11: 0 | H11: 0 | I11: 0 | J11: 0 | K11: 0 | L11: 0 | M11: 0 | N11: 0 | O11: 0 | P11: =+(G11*E11)+(H11+I11+J11)+(((K11+L11+O11)*E11/2))+(((M11+N11)*E11)) -> 0 | Q11: =IF(D11=Listas!$B$41,SUM(P11*1227)/1227,0) -> 0 | R11: =IF(D11=Listas!$B$42,SUM(P11*1403)/1227,0) -> 0 | S11: =IF(D11=Listas!$B$43,SUM(P11*1636)/1227,0) -> 0 | T11: =+Q11+R11+S11 -> 0 | U11: =IF(C11=Listas!$B$18,((T11*1227)*23%)+(T11*1227),IF(C11=Listas!$B$19,((T11*1227)*56%)+(T11*1227),IF(C11=Listas!$B$20,((T11*1227)*69%)+(T11*1227),IF(C11=Listas!$B$21,((T11*1227)*31%)+(T11*1227),IF(C11=Listas!$B$22,((T11*1227)*11%)+(T11*1227),IF(C11=Listas!$B$17,((T11*1227)*0%)+(T11*1227)))))))/1227.66 -> 0 | V11: =+U11 -> 0 | X11: 0 | Y11: 0 | Z11: 0 | AA11: 0 | AB11: =(IF(Y11=Listas!$B$41,SUM(IF(Z11=Listas!$B$27,SUM(AA11*1227),IF(Z11=Listas!$B$28,SUM(AA11*1841),IF(Z11=Listas!$B$29,SUM(AA11*2455)))))))/1227 -> 0 | AC11: =(IF(Y11=Listas!$B$42,SUM(IF(Z11=Listas!$B$27,SUM(AA11*1403),IF(Z11=Listas!$B$28,SUM(AA11*2104),IF(Z11=Listas!$B$29,SUM(AA11*2806)))))))/1227 -> 0 | AD11: =(IF(Y11=Listas!$B$43,SUM(IF(Z11=Listas!$B$27,SUM(AA11*1636),IF(Z11=Listas!$B$28,SUM(AA11*2454),IF(Z11=Listas!$B$29,SUM(AA11*3272)))))))/1227 -> 0 | AE11: =SUM(AB11:AD11) -> 0 | AF11: =(IF(X11=Listas!$B$18,+(AE11*23%)+(AE11),IF(X11=Listas!$B$19,+(AE11*56%)+(AE11),IF(X11=Listas!$B$20,+(AE11*103%)+(AE11),IF(X11=Listas!$B$21,+(AE11*31%)+(AE11),IF(X11=Listas!$B$22,+(AE11*11%)+(AE11),IF(X11=Listas!$B$17,+(AE11*0%)+(AE11),0))))))) -> 0
C12: 0 | D12: 0 | E12: =(IF(F12=Listas!$B$7,"8",IF(F12=Listas!$B$8,"7",IF(F12=Listas!$B$9,"6",IF(F12=Listas!$B$10,"7",IF(F12=Listas!$B$11,"6.125",IF(F12=Listas!$B$12,"5.250",IF(F12=Listas!$B$6,"0")))))))) -> 0 | F12: 0 | G12: 0 | H12: 0 | I12: 0 | J12: 0 | K12: 0 | L12: 0 | M12: 0 | N12: 0 | O12: 0 | P12: =+(G12*E12)+(H12+I12+J12)+(((K12+L12+O12)*E12/2))+(((M12+N12)*E12)) -> 0 | Q12: =IF(D12=Listas!$B$41,SUM(P12*1227)/1227,0) -> 0 | R12: =IF(D12=Listas!$B$42,SUM(P12*1403)/1227,0) -> 0 | S12: =IF(D12=Listas!$B$43,SUM(P12*1636)/1227,0) -> 0 | T12: =+Q12+R12+S12 -> 0 | U12: =IF(C12=Listas!$B$18,((T12*1227)*23%)+(T12*1227),IF(C12=Listas!$B$19,((T12*1227)*56%)+(T12*1227),IF(C12=Listas!$B$20,((T12*1227)*69%)+(T12*1227),IF(C12=Listas!$B$21,((T12*1227)*31%)+(T12*1227),IF(C12=Listas!$B$22,((T12*1227)*11%)+(T12*1227),IF(C12=Listas!$B$17,((T12*1227)*0%)+(T12*1227)))))))/1227.66 -> 0 | V12: =+U12 -> 0 | X12: 0 | Y12: 0 | Z12: 0 | AA12: 0 | AB12: =(IF(Y12=Listas!$B$41,SUM(IF(Z12=Listas!$B$27,SUM(AA12*1227),IF(Z12=Listas!$B$28,SUM(AA12*1841),IF(Z12=Listas!$B$29,SUM(AA12*2455)))))))/1227 -> 0 | AC12: =(IF(Y12=Listas!$B$42,SUM(IF(Z12=Listas!$B$27,SUM(AA12*1403),IF(Z12=Listas!$B$28,SUM(AA12*2104),IF(Z12=Listas!$B$29,SUM(AA12*2806)))))))/1227 -> 0 | AD12: =(IF(Y12=Listas!$B$43,SUM(IF(Z12=Listas!$B$27,SUM(AA12*1636),IF(Z12=Listas!$B$28,SUM(AA12*2454),IF(Z12=Listas!$B$29,SUM(AA12*3272)))))))/1227 -> 0 | AE12: =SUM(AB12:AD12) -> 0 | AF12: =(IF(X12=Listas!$B$18,+(AE12*23%)+(AE12),IF(X12=Listas!$B$19,+(AE12*56%)+(AE12),IF(X12=Listas!$B$20,+(AE12*103%)+(AE12),IF(X12=Listas!$B$21,+(AE12*31%)+(AE12),IF(X12=Listas!$B$22,+(AE12*11%)+(AE12),IF(X12=Listas!$B$17,+(AE12*0%)+(AE12),0))))))) -> 0
C13: 0 | D13: 0 | E13: =(IF(F13=Listas!$B$7,"8",IF(F13=Listas!$B$8,"7",IF(F13=Listas!$B$9,"6",IF(F13=Listas!$B$10,"7",IF(F13=Listas!$B$11,"6.125",IF(F13=Listas!$B$12,"5.250",IF(F13=Listas!$B$6,"0")))))))) -> 0 | F13: 0 | G13: 0 | H13: 0 | I13: 0 | J13: 0 | K13: 0 | L13: 0 | M13: 0 | N13: 0 | O13: 0 | P13: =+(G13*E13)+(H13+I13+J13)+(((K13+L13+O13)*E13/2))+(((M13+N13)*E13)) -> 0 | Q13: =IF(D13=Listas!$B$41,SUM(P13*1227)/1227,0) -> 0 | R13: =IF(D13=Listas!$B$42,SUM(P13*1403)/1227,0) -> 0 | S13: =IF(D13=Listas!$B$43,SUM(P13*1636)/1227,0) -> 0 | T13: =+Q13+R13+S13 -> 0 | U13: =IF(C13=Listas!$B$18,((T13*1227)*23%)+(T13*1227),IF(C13=Listas!$B$19,((T13*1227)*56%)+(T13*1227),IF(C13=Listas!$B$20,((T13*1227)*69%)+(T13*1227),IF(C13=Listas!$B$21,((T13*1227)*31%)+(T13*1227),IF(C13=Listas!$B$22,((T13*1227)*11%)+(T13*1227),IF(C13=Listas!$B$17,((T13*1227)*0%)+(T13*1227)))))))/1227.66 -> 0 | V13: =+U13 -> 0 | X13: 0 | Y13: 0 | Z13: 0 | AA13: 0 | AB13: =(IF(Y13=Listas!$B$41,SUM(IF(Z13=Listas!$B$27,SUM(AA13*1227),IF(Z13=Listas!$B$28,SUM(AA13*1841),IF(Z13=Listas!$B$29,SUM(AA13*2455)))))))/1227 -> 0 | AC13: =(IF(Y13=Listas!$B$42,SUM(IF(Z13=Listas!$B$27,SUM(AA13*1403),IF(Z13=Listas!$B$28,SUM(AA13*2104),IF(Z13=Listas!$B$29,SUM(AA13*2806)))))))/1227 -> 0 | AD13: =(IF(Y13=Listas!$B$43,SUM(IF(Z13=Listas!$B$27,SUM(AA13*1636),IF(Z13=Listas!$B$28,SUM(AA13*2454),IF(Z13=Listas!$B$29,SUM(AA13*3272)))))))/1227 -> 0 | AE13: =SUM(AB13:AD13) -> 0 | AF13: =(IF(X13=Listas!$B$18,+(AE13*23%)+(AE13),IF(X13=Listas!$B$19,+(AE13*56%)+(AE13),IF(X13=Listas!$B$20,+(AE13*103%)+(AE13),IF(X13=Listas!$B$21,+(AE13*31%)+(AE13),IF(X13=Listas!$B$22,+(AE13*11%)+(AE13),IF(X13=Listas!$B$17,+(AE13*0%)+(AE13),0))))))) -> 0
C14: 0 | D14: 0 | E14: =(IF(F14=Listas!$B$7,"8",IF(F14=Listas!$B$8,"7",IF(F14=Listas!$B$9,"6",IF(F14=Listas!$B$10,"7",IF(F14=Listas!$B$11,"6.125",IF(F14=Listas!$B$12,"5.250",IF(F14=Listas!$B$6,"0")))))))) -> 0 | F14: 0 | G14: 0 | H14: 0 | I14: 0 | J14: 0 | K14: 0 | L14: 0 | M14: 0 | N14: 0 | O14: 0 | P14: =+(G14*E14)+(H14+I14+J14)+(((K14+L14+O14)*E14/2))+(((M14+N14)*E14)) -> 0 | Q14: =IF(D14=Listas!$B$41,SUM(P14*1227)/1227,0) -> 0 | R14: =IF(D14=Listas!$B$42,SUM(P14*1403)/1227,0) -> 0 | S14: =IF(D14=Listas!$B$43,SUM(P14*1636)/1227,0) -> 0 | T14: =+Q14+R14+S14 -> 0 | U14: =IF(C14=Listas!$B$18,((T14*1227)*23%)+(T14*1227),IF(C14=Listas!$B$19,((T14*1227)*56%)+(T14*1227),IF(C14=Listas!$B$20,((T14*1227)*69%)+(T14*1227),IF(C14=Listas!$B$21,((T14*1227)*31%)+(T14*1227),IF(C14=Listas!$B$22,((T14*1227)*11%)+(T14*1227),IF(C14=Listas!$B$17,((T14*1227)*0%)+(T14*1227)))))))/1227.66 -> 0 | V14: =+U14 -> 0 | X14: 0 | Y14: 0 | Z14: 0 | AA14: 0 | AB14: =(IF(Y14=Listas!$B$41,SUM(IF(Z14=Listas!$B$27,SUM(AA14*1227),IF(Z14=Listas!$B$28,SUM(AA14*1841),IF(Z14=Listas!$B$29,SUM(AA14*2455)))))))/1227 -> 0 | AC14: =(IF(Y14=Listas!$B$42,SUM(IF(Z14=Listas!$B$27,SUM(AA14*1403),IF(Z14=Listas!$B$28,SUM(AA14*2104),IF(Z14=Listas!$B$29,SUM(AA14*2806)))))))/1227 -> 0 | AD14: =(IF(Y14=Listas!$B$43,SUM(IF(Z14=Listas!$B$27,SUM(AA14*1636),IF(Z14=Listas!$B$28,SUM(AA14*2454),IF(Z14=Listas!$B$29,SUM(AA14*3272)))))))/1227 -> 0 | AE14: =SUM(AB14:AD14) -> 0 | AF14: =(IF(X14=Listas!$B$18,+(AE14*23%)+(AE14),IF(X14=Listas!$B$19,+(AE14*56%)+(AE14),IF(X14=Listas!$B$20,+(AE14*103%)+(AE14),IF(X14=Listas!$B$21,+(AE14*31%)+(AE14),IF(X14=Listas!$B$22,+(AE14*11%)+(AE14),IF(X14=Listas!$B$17,+(AE14*0%)+(AE14),0))))))) -> 0
C15: 0 | D15: 0 | E15: =(IF(F15=Listas!$B$7,"8",IF(F15=Listas!$B$8,"7",IF(F15=Listas!$B$9,"6",IF(F15=Listas!$B$10,"7",IF(F15=Listas!$B$11,"6.125",IF(F15=Listas!$B$12,"5.250",IF(F15=Listas!$B$6,"0")))))))) -> 0 | F15: 0 | G15: 0 | H15: 0 | I15: 0 | J15: 0 | K15: 0 | L15: 0 | M15: 0 | N15: 0 | O15: 0 | P15: =+(G15*E15)+(H15+I15+J15)+(((K15+L15+O15)*E15/2))+(((M15+N15)*E15)) -> 0 | Q15: =IF(D15=Listas!$B$41,SUM(P15*1227)/1227,0) -> 0 | R15: =IF(D15=Listas!$B$42,SUM(P15*1403)/1227,0) -> 0 | S15: =IF(D15=Listas!$B$43,SUM(P15*1636)/1227,0) -> 0 | T15: =+Q15+R15+S15 -> 0 | U15: =IF(C15=Listas!$B$18,((T15*1227)*23%)+(T15*1227),IF(C15=Listas!$B$19,((T15*1227)*56%)+(T15*1227),IF(C15=Listas!$B$20,((T15*1227)*69%)+(T15*1227),IF(C15=Listas!$B$21,((T15*1227)*31%)+(T15*1227),IF(C15=Listas!$B$22,((T15*1227)*11%)+(T15*1227),IF(C15=Listas!$B$17,((T15*1227)*0%)+(T15*1227)))))))/1227.66 -> 0 | V15: =+U15 -> 0 | X15: 0 | Y15: 0 | Z15: 0 | AA15: 0 | AB15: =(IF(Y15=Listas!$B$41,SUM(IF(Z15=Listas!$B$27,SUM(AA15*1227),IF(Z15=Listas!$B$28,SUM(AA15*1841),IF(Z15=Listas!$B$29,SUM(AA15*2455)))))))/1227 -> 0 | AC15: =(IF(Y15=Listas!$B$42,SUM(IF(Z15=Listas!$B$27,SUM(AA15*1403),IF(Z15=Listas!$B$28,SUM(AA15*2104),IF(Z15=Listas!$B$29,SUM(AA15*2806)))))))/1227 -> 0 | AD15: =(IF(Y15=Listas!$B$43,SUM(IF(Z15=Listas!$B$27,SUM(AA15*1636),IF(Z15=Listas!$B$28,SUM(AA15*2454),IF(Z15=Listas!$B$29,SUM(AA15*3272)))))))/1227 -> 0 | AE15: =SUM(AB15:AD15) -> 0 | AF15: =(IF(X15=Listas!$B$18,+(AE15*23%)+(AE15),IF(X15=Listas!$B$19,+(AE15*56%)+(AE15),IF(X15=Listas!$B$20,+(AE15*103%)+(AE15),IF(X15=Listas!$B$21,+(AE15*31%)+(AE15),IF(X15=Listas!$B$22,+(AE15*11%)+(AE15),IF(X15=Listas!$B$17,+(AE15*0%)+(AE15),0))))))) -> 0
C16: 0 | D16: 0 | E16: =(IF(F16=Listas!$B$7,"8",IF(F16=Listas!$B$8,"7",IF(F16=Listas!$B$9,"6",IF(F16=Listas!$B$10,"7",IF(F16=Listas!$B$11,"6.125",IF(F16=Listas!$B$12,"5.250",IF(F16=Listas!$B$6,"0")))))))) -> 0 | F16: 0 | G16: 0 | H16: 0 | I16: 0 | J16: 0 | K16: 0 | L16: 0 | M16: 0 | N16: 0 | O16: 0 | P16: =+(G16*E16)+(H16+I16+J16)+(((K16+L16+O16)*E16/2))+(((M16+N16)*E16)) -> 0 | Q16: =IF(D16=Listas!$B$41,SUM(P16*1227)/1227,0) -> 0 | R16: =IF(D16=Listas!$B$42,SUM(P16*1403)/1227,0) -> 0 | S16: =IF(D16=Listas!$B$43,SUM(P16*1636)/1227,0) -> 0 | T16: =+Q16+R16+S16 -> 0 | U16: =IF(C16=Listas!$B$18,((T16*1227)*23%)+(T16*1227),IF(C16=Listas!$B$19,((T16*1227)*56%)+(T16*1227),IF(C16=Listas!$B$20,((T16*1227)*69%)+(T16*1227),IF(C16=Listas!$B$21,((T16*1227)*31%)+(T16*1227),IF(C16=Listas!$B$22,((T16*1227)*11%)+(T16*1227),IF(C16=Listas!$B$17,((T16*1227)*0%)+(T16*1227)))))))/1227.66 -> 0 | V16: =+U16 -> 0 | X16: 0 | Y16: 0 | Z16: 0 | AA16: 0 | AB16: =(IF(Y16=Listas!$B$41,SUM(IF(Z16=Listas!$B$27,SUM(AA16*1227),IF(Z16=Listas!$B$28,SUM(AA16*1841),IF(Z16=Listas!$B$29,SUM(AA16*2455)))))))/1227 -> 0 | AC16: =(IF(Y16=Listas!$B$42,SUM(IF(Z16=Listas!$B$27,SUM(AA16*1403),IF(Z16=Listas!$B$28,SUM(AA16*2104),IF(Z16=Listas!$B$29,SUM(AA16*2806)))))))/1227 -> 0 | AD16: =(IF(Y16=Listas!$B$43,SUM(IF(Z16=Listas!$B$27,SUM(AA16*1636),IF(Z16=Listas!$B$28,SUM(AA16*2454),IF(Z16=Listas!$B$29,SUM(AA16*3272)))))))/1227 -> 0 | AE16: =SUM(AB16:AD16) -> 0 | AF16: =(IF(X16=Listas!$B$18,+(AE16*23%)+(AE16),IF(X16=Listas!$B$19,+(AE16*56%)+(AE16),IF(X16=Listas!$B$20,+(AE16*103%)+(AE16),IF(X16=Listas!$B$21,+(AE16*31%)+(AE16),IF(X16=Listas!$B$22,+(AE16*11%)+(AE16),IF(X16=Listas!$B$17,+(AE16*0%)+(AE16),0))))))) -> 0
C17: 0 | D17: 0 | E17: =(IF(F17=Listas!$B$7,"8",IF(F17=Listas!$B$8,"7",IF(F17=Listas!$B$9,"6",IF(F17=Listas!$B$10,"7",IF(F17=Listas!$B$11,"6.125",IF(F17=Listas!$B$12,"5.250",IF(F17=Listas!$B$6,"0")))))))) -> 0 | F17: 0 | G17: 0 | H17: 0 | I17: 0 | J17: 0 | K17: 0 | L17: 0 | M17: 0 | N17: 0 | O17: 0 | P17: =+(G17*E17)+(H17+I17+J17)+(((K17+L17+O17)*E17/2))+(((M17+N17)*E17)) -> 0 | Q17: =IF(D17=Listas!$B$41,SUM(P17*1227)/1227,0) -> 0 | R17: =IF(D17=Listas!$B$42,SUM(P17*1403)/1227,0) -> 0 | S17: =IF(D17=Listas!$B$43,SUM(P17*1636)/1227,0) -> 0 | T17: =+Q17+R17+S17 -> 0 | U17: =IF(C17=Listas!$B$18,((T17*1227)*23%)+(T17*1227),IF(C17=Listas!$B$19,((T17*1227)*56%)+(T17*1227),IF(C17=Listas!$B$20,((T17*1227)*69%)+(T17*1227),IF(C17=Listas!$B$21,((T17*1227)*31%)+(T17*1227),IF(C17=Listas!$B$22,((T17*1227)*11%)+(T17*1227),IF(C17=Listas!$B$17,((T17*1227)*0%)+(T17*1227)))))))/1227.66 -> 0 | V17: =+U17 -> 0 | X17: 0 | Y17: 0 | Z17: 0 | AA17: 0 | AB17: =(IF(Y17=Listas!$B$41,SUM(IF(Z17=Listas!$B$27,SUM(AA17*1227),IF(Z17=Listas!$B$28,SUM(AA17*1841),IF(Z17=Listas!$B$29,SUM(AA17*2455)))))))/1227 -> 0 | AC17: =(IF(Y17=Listas!$B$42,SUM(IF(Z17=Listas!$B$27,SUM(AA17*1403),IF(Z17=Listas!$B$28,SUM(AA17*2104),IF(Z17=Listas!$B$29,SUM(AA17*2806)))))))/1227 -> 0 | AD17: =(IF(Y17=Listas!$B$43,SUM(IF(Z17=Listas!$B$27,SUM(AA17*1636),IF(Z17=Listas!$B$28,SUM(AA17*2454),IF(Z17=Listas!$B$29,SUM(AA17*3272)))))))/1227 -> 0 | AE17: =SUM(AB17:AD17) -> 0 | AF17: =(IF(X17=Listas!$B$18,+(AE17*23%)+(AE17),IF(X17=Listas!$B$19,+(AE17*56%)+(AE17),IF(X17=Listas!$B$20,+(AE17*103%)+(AE17),IF(X17=Listas!$B$21,+(AE17*31%)+(AE17),IF(X17=Listas!$B$22,+(AE17*11%)+(AE17),IF(X17=Listas!$B$17,+(AE17*0%)+(AE17),0))))))) -> 0
C18: 0 | D18: 0 | E18: =(IF(F18=Listas!$B$7,"8",IF(F18=Listas!$B$8,"7",IF(F18=Listas!$B$9,"6",IF(F18=Listas!$B$10,"7",IF(F18=Listas!$B$11,"6.125",IF(F18=Listas!$B$12,"5.250",IF(F18=Listas!$B$6,"0")))))))) -> 0 | F18: 0 | G18: 0 | H18: 0 | I18: 0 | J18: 0 | K18: 0 | L18: 0 | M18: 0 | N18: 0 | O18: 0 | P18: =+(G18*E18)+(H18+I18+J18)+(((K18+L18+O18)*E18/2))+(((M18+N18)*E18)) -> 0 | Q18: =IF(D18=Listas!$B$41,SUM(P18*1227)/1227,0) -> 0 | R18: =IF(D18=Listas!$B$42,SUM(P18*1403)/1227,0) -> 0 | S18: =IF(D18=Listas!$B$43,SUM(P18*1636)/1227,0) -> 0 | T18: =+Q18+R18+S18 -> 0 | U18: =IF(C18=Listas!$B$18,((T18*1227)*23%)+(T18*1227),IF(C18=Listas!$B$19,((T18*1227)*56%)+(T18*1227),IF(C18=Listas!$B$20,((T18*1227)*69%)+(T18*1227),IF(C18=Listas!$B$21,((T18*1227)*31%)+(T18*1227),IF(C18=Listas!$B$22,((T18*1227)*11%)+(T18*1227),IF(C18=Listas!$B$17,((T18*1227)*0%)+(T18*1227)))))))/1227.66 -> 0 | V18: =+U18 -> 0 | X18: 0 | Y18: 0 | Z18: 0 | AA18: 0 | AB18: =(IF(Y18=Listas!$B$41,SUM(IF(Z18=Listas!$B$27,SUM(AA18*1227),IF(Z18=Listas!$B$28,SUM(AA18*1841),IF(Z18=Listas!$B$29,SUM(AA18*2455)))))))/1227 -> 0 | AC18: =(IF(Y18=Listas!$B$42,SUM(IF(Z18=Listas!$B$27,SUM(AA18*1403),IF(Z18=Listas!$B$28,SUM(AA18*2104),IF(Z18=Listas!$B$29,SUM(AA18*2806)))))))/1227 -> 0 | AD18: =(IF(Y18=Listas!$B$43,SUM(IF(Z18=Listas!$B$27,SUM(AA18*1636),IF(Z18=Listas!$B$28,SUM(AA18*2454),IF(Z18=Listas!$B$29,SUM(AA18*3272)))))))/1227 -> 0 | AE18: =SUM(AB18:AD18) -> 0 | AF18: =(IF(X18=Listas!$B$18,+(AE18*23%)+(AE18),IF(X18=Listas!$B$19,+(AE18*56%)+(AE18),IF(X18=Listas!$B$20,+(AE18*103%)+(AE18),IF(X18=Listas!$B$21,+(AE18*31%)+(AE18),IF(X18=Listas!$B$22,+(AE18*11%)+(AE18),IF(X18=Listas!$B$17,+(AE18*0%)+(AE18),0))))))) -> 0
C19: 0 | D19: 0 | E19: =(IF(F19=Listas!$B$7,"8",IF(F19=Listas!$B$8,"7",IF(F19=Listas!$B$9,"6",IF(F19=Listas!$B$10,"7",IF(F19=Listas!$B$11,"6.125",IF(F19=Listas!$B$12,"5.250",IF(F19=Listas!$B$6,"0")))))))) -> 0 | F19: 0 | G19: 0 | H19: 0 | I19: 0 | J19: 0 | K19: 0 | L19: 0 | M19: 0 | N19: 0 | O19: 0 | P19: =+(G19*E19)+(H19+I19+J19)+(((K19+L19+O19)*E19/2))+(((M19+N19)*E19)) -> 0 | Q19: =IF(D19=Listas!$B$41,SUM(P19*1227)/1227,0) -> 0 | R19: =IF(D19=Listas!$B$42,SUM(P19*1403)/1227,0) -> 0 | S19: =IF(D19=Listas!$B$43,SUM(P19*1636)/1227,0) -> 0 | T19: =+Q19+R19+S19 -> 0 | U19: =IF(C19=Listas!$B$18,((T19*1227)*23%)+(T19*1227),IF(C19=Listas!$B$19,((T19*1227)*56%)+(T19*1227),IF(C19=Listas!$B$20,((T19*1227)*69%)+(T19*1227),IF(C19=Listas!$B$21,((T19*1227)*31%)+(T19*1227),IF(C19=Listas!$B$22,((T19*1227)*11%)+(T19*1227),IF(C19=Listas!$B$17,((T19*1227)*0%)+(T19*1227)))))))/1227.66 -> 0 | V19: =+U19 -> 0 | X19: 0 | Y19: 0 | Z19: 0 | AA19: 0 | AB19: =(IF(Y19=Listas!$B$41,SUM(IF(Z19=Listas!$B$27,SUM(AA19*1227),IF(Z19=Listas!$B$28,SUM(AA19*1841),IF(Z19=Listas!$B$29,SUM(AA19*2455)))))))/1227 -> 0 | AC19: =(IF(Y19=Listas!$B$42,SUM(IF(Z19=Listas!$B$27,SUM(AA19*1403),IF(Z19=Listas!$B$28,SUM(AA19*2104),IF(Z19=Listas!$B$29,SUM(AA19*2806)))))))/1227 -> 0 | AD19: =(IF(Y19=Listas!$B$43,SUM(IF(Z19=Listas!$B$27,SUM(AA19*1636),IF(Z19=Listas!$B$28,SUM(AA19*2454),IF(Z19=Listas!$B$29,SUM(AA19*3272)))))))/1227 -> 0 | AE19: =SUM(AB19:AD19) -> 0 | AF19: =(IF(X19=Listas!$B$18,+(AE19*23%)+(AE19),IF(X19=Listas!$B$19,+(AE19*56%)+(AE19),IF(X19=Listas!$B$20,+(AE19*103%)+(AE19),IF(X19=Listas!$B$21,+(AE19*31%)+(AE19),IF(X19=Listas!$B$22,+(AE19*11%)+(AE19),IF(X19=Listas!$B$17,+(AE19*0%)+(AE19),0))))))) -> 0
C20: 0 | D20: 0 | E20: =(IF(F20=Listas!$B$7,"8",IF(F20=Listas!$B$8,"7",IF(F20=Listas!$B$9,"6",IF(F20=Listas!$B$10,"7",IF(F20=Listas!$B$11,"6.125",IF(F20=Listas!$B$12,"5.250",IF(F20=Listas!$B$6,"0")))))))) -> 0 | F20: 0 | G20: 0 | H20: 0 | I20: 0 | J20: 0 | K20: 0 | L20: 0 | M20: 0 | N20: 0 | O20: 0 | P20: =+(G20*E20)+(H20+I20+J20)+(((K20+L20+O20)*E20/2))+(((M20+N20)*E20)) -> 0 | Q20: =IF(D20=Listas!$B$41,SUM(P20*1227)/1227,0) -> 0 | R20: =IF(D20=Listas!$B$42,SUM(P20*1403)/1227,0) -> 0 | S20: =IF(D20=Listas!$B$43,SUM(P20*1636)/1227,0) -> 0 | T20: =+Q20+R20+S20 -> 0 | U20: =IF(C20=Listas!$B$18,((T20*1227)*23%)+(T20*1227),IF(C20=Listas!$B$19,((T20*1227)*56%)+(T20*1227),IF(C20=Listas!$B$20,((T20*1227)*69%)+(T20*1227),IF(C20=Listas!$B$21,((T20*1227)*31%)+(T20*1227),IF(C20=Listas!$B$22,((T20*1227)*11%)+(T20*1227),IF(C20=Listas!$B$17,((T20*1227)*0%)+(T20*1227)))))))/1227.66 -> 0 | V20: =+U20 -> 0 | X20: 0 | Y20: 0 | Z20: 0 | AA20: 0 | AB20: =(IF(Y20=Listas!$B$41,SUM(IF(Z20=Listas!$B$27,SUM(AA20*1227),IF(Z20=Listas!$B$28,SUM(AA20*1841),IF(Z20=Listas!$B$29,SUM(AA20*2455)))))))/1227 -> 0 | AC20: =(IF(Y20=Listas!$B$42,SUM(IF(Z20=Listas!$B$27,SUM(AA20*1403),IF(Z20=Listas!$B$28,SUM(AA20*2104),IF(Z20=Listas!$B$29,SUM(AA20*2806)))))))/1227 -> 0 | AD20: =(IF(Y20=Listas!$B$43,SUM(IF(Z20=Listas!$B$27,SUM(AA20*1636),IF(Z20=Listas!$B$28,SUM(AA20*2454),IF(Z20=Listas!$B$29,SUM(AA20*3272)))))))/1227 -> 0 | AE20: =SUM(AB20:AD20) -> 0 | AF20: =(IF(X20=Listas!$B$18,+(AE20*23%)+(AE20),IF(X20=Listas!$B$19,+(AE20*56%)+(AE20),IF(X20=Listas!$B$20,+(AE20*103%)+(AE20),IF(X20=Listas!$B$21,+(AE20*31%)+(AE20),IF(X20=Listas!$B$22,+(AE20*11%)+(AE20),IF(X20=Listas!$B$17,+(AE20*0%)+(AE20),0))))))) -> 0
... C56: 0 | D56: 0 | E56: =(IF(F56=Listas!$B$7,"8",IF(F56=Listas!$B$8,"7",IF(F56=Listas!$B$9,"6",IF(F56=Listas!$B$10,"7",IF(F56=Listas!$B$11,"6.125",IF(F56=Listas!$B$12,"5.250",IF(F56=Listas!$B$6,"0")))))))) -> 0 | F56: 0 | G56: 0 | H56: 0 | I56: 0 | J56: 0 | K56: 0 | L56: 0 | M56: 0 | N56: 0 | O56: 0 | P56: =+(G56*E56)+(H56+I56+J56)+(((K56+L56+O56)*E56/2))+(((M56+N56)*E56)) -> 0 | Q56: =IF(D56=Listas!$B$41,SUM(P56*1227)/1227,0) -> 0 | R56: =IF(D56=Listas!$B$42,SUM(P56*1403)/1227,0) -> 0 | S56: =IF(D56=Listas!$B$43,SUM(P56*1636)/1227,0) -> 0 | T56: =+Q56+R56+S56 -> 0 | U56: =IF(C56=Listas!$B$18,((T56*1227)*23%)+(T56*1227),IF(C56=Listas!$B$19,((T56*1227)*56%)+(T56*1227),IF(C56=Listas!$B$20,((T56*1227)*69%)+(T56*1227),IF(C56=Listas!$B$21,((T56*1227)*31%)+(T56*1227),IF(C56=Listas!$B$22,((T56*1227)*11%)+(T56*1227),IF(C56=Listas!$B$17,((T56*1227)*0%)+(T56*1227)))))))/1227.66 -> 0 | V56: =+U56 -> 0 | X56: 0 | Y56: 0 | Z56: 0 | AA56: 0 | AB56: =(IF(Y56=Listas!$B$41,SUM(IF(Z56=Listas!$B$27,SUM(AA56*1227),IF(Z56=Listas!$B$28,SUM(AA56*1841),IF(Z56=Listas!$B$29,SUM(AA56*2455)))))))/1227 -> 0 | AC56: =(IF(Y56=Listas!$B$42,SUM(IF(Z56=Listas!$B$27,SUM(AA56*1403),IF(Z56=Listas!$B$28,SUM(AA56*2104),IF(Z56=Listas!$B$29,SUM(AA56*2806)))))))/1227 -> 0 | AD56: =(IF(Y56=Listas!$B$43,SUM(IF(Z56=Listas!$B$27,SUM(AA56*1636),IF(Z56=Listas!$B$28,SUM(AA56*2454),IF(Z56=Listas!$B$29,SUM(AA56*3272)))))))/1227 -> 0 | AE56: =SUM(AB56:AD56) -> 0 | AF56: =(IF(X56=Listas!$B$18,+(AE56*23%)+(AE56),IF(X56=Listas!$B$19,+(AE56*56%)+(AE56),IF(X56=Listas!$B$20,+(AE56*103%)+(AE56),IF(X56=Listas!$B$21,+(AE56*31%)+(AE56),IF(X56=Listas!$B$22,+(AE56*11%)+(AE56),IF(X56=Listas!$B$17,+(AE56*0%)+(AE56),0))))))) -> 0
B57: TOTALES | G57: =SUM(G9:G56) -> 0 | H57: =SUM(H9:H56) -> 0 | I57: =SUM(I9:I56) -> 0 | J57: =SUM(J9:J56) -> 0 | K57: =SUM(K9:K56) -> 0 | L57: =SUM(L9:L56) -> 0 | M57: =SUM(M9:M56) -> 0 | N57: =SUM(N9:N56) -> 0 | ... W57: =SUM(W9:W56) -> 0 | AA57: =SUM(AA9:AA56) -> 0 | AB57: =SUM(AB9:AB56) -> 0 | AC57: =SUM(AC9:AC56) -> 0 | AD57: =SUM(AD9:AD56) -> 0 | AE57: =SUM(AE9:AE56) -> 0 | AF57: =SUM(AF9:AF56) -> 0

Sheet 3
F2: FECHA | G2: PROYECTO | V2: =+'1'!$V$2 -> RIGE A PARTIR DEL 23 DE FEBRERO 2026 | Z2: Tiempo Ordinario Disponible | AA2: Horas asignadas | AF2: Saldo de Horas
V3: =+'1'!$V$3 -> RH-F-24- Control de Horas Diarias
F4: =+'2'!F4+1 -> 46078 | G4: =+'1'!$G$4 -> - | V4: =+'1'!$V$4 -> Rige: 16/03/2026 Versión:1 | Z4: =+V57 -> 0 | AA4: =-AF57 -> 0 | AF4: =+Z4+AA4+'2'!AF4 -> 0
B7: Nota: Llenar únicamente las celdas en color amarillo. | G7: Anote un 1 si la plaza está vacantes | H7: Según Acción de Personal | Q7: CALCULOS
B8: Nombre del funcionario con Acción de Personal | C8: Elija el puesto del funcionario | D8: Elija el Horario General | E8: Jornada | F8: Elija la Jornada | H8: Digite horas por Ausencias Injustifica-das | I8: Digite horas por Ausencias Justifica-das | J8: Digite horas por Permisos sin Goce de Salario | K8: Anote un 1 si está en Licencia por Maternidad o Paternidad | L8: Anote un 1 si está incapacitado por la CCSS, 3 primeros días | M8: Anote un 1 si está incapacita-do por la CCSS, del 4tp día en adelante | N8: Anote un 1 si está incapacitado por el INS | O8: Anote un 1 si está de Vacaciones | P8: Total de Horas | Q8: Día | R8: Tarde Noche | S8: Noche | T8: Total Horas | V8: Horas Ordinarias Disponibles convertidas a día | W8: Quién las laborará | X8: Elija el puesto del funcionario | Y8: Elija el Horario General | Z8: Elija el tipo de horas a Calcular | AA8: Digite las horas Aprobadas a Trabajar | AB8: Día | AC8: Tarde Noche | AD8: Noche | AE8: Total Horas Ordinarias convertidas a Dia | AF8: Total Horas Ordinarias convertidas a Dia
C9: 0 | D9: 0 | E9: =(IF(F9=Listas!$B$7,"8",IF(F9=Listas!$B$8,"7",IF(F9=Listas!$B$9,"6",IF(F9=Listas!$B$10,"7",IF(F9=Listas!$B$11,"6.125",IF(F9=Listas!$B$12,"5.250",IF(F9=Listas!$B$6,"0")))))))) -> 0 | F9: 0 | G9: 0 | H9: 0 | I9: 0 | J9: 0 | K9: 0 | L9: 0 | M9: 0 | N9: 0 | O9: 0 | P9: =+(G9*E9)+(H9+I9+J9)+(((K9+L9+O9)*E9/2))+(((M9+N9)*E9)) -> 0 | Q9: =IF(D9=Listas!$B$41,SUM(P9*1227)/1227,0) -> 0 | R9: =IF(D9=Listas!$B$42,SUM(P9*1403)/1227,0) -> 0 | S9: =IF(D9=Listas!$B$43,SUM(P9*1636)/1227,0) -> 0 | T9: =+Q9+R9+S9 -> 0 | U9: =IF(C9=Listas!$B$18,((T9*1227)*23%)+(T9*1227),IF(C9=Listas!$B$19,((T9*1227)*56%)+(T9*1227),IF(C9=Listas!$B$20,((T9*1227)*69%)+(T9*1227),IF(C9=Listas!$B$21,((T9*1227)*31%)+(T9*1227),IF(C9=Listas!$B$22,((T9*1227)*11%)+(T9*1227),IF(C9=Listas!$B$17,((T9*1227)*0%)+(T9*1227)))))))/1227.66 -> 0 | V9: =+U9 -> 0 | X9: 0 | Y9: 0 | Z9: 0 | AA9: 0 | AB9: =(IF(Y9=Listas!$B$41,SUM(IF(Z9=Listas!$B$27,SUM(AA9*1227),IF(Z9=Listas!$B$28,SUM(AA9*1841),IF(Z9=Listas!$B$29,SUM(AA9*2455)))))))/1227 -> 0 | AC9: =(IF(Y9=Listas!$B$42,SUM(IF(Z9=Listas!$B$27,SUM(AA9*1403),IF(Z9=Listas!$B$28,SUM(AA9*2104),IF(Z9=Listas!$B$29,SUM(AA9*2806)))))))/1227 -> 0 | AD9: =(IF(Y9=Listas!$B$43,SUM(IF(Z9=Listas!$B$27,SUM(AA9*1636),IF(Z9=Listas!$B$28,SUM(AA9*2454),IF(Z9=Listas!$B$29,SUM(AA9*3272)))))))/1227 -> 0 | AE9: =SUM(AB9:AD9) -> 0 | AF9: =(IF(X9=Listas!$B$18,+(AE9*23%)+(AE9),IF(X9=Listas!$B$19,+(AE9*56%)+(AE9),IF(X9=Listas!$B$20,+(AE9*103%)+(AE9),IF(X9=Listas!$B$21,+(AE9*31%)+(AE9),IF(X9=Listas!$B$22,+(AE9*11%)+(AE9),IF(X9=Listas!$B$17,+(AE9*0%)+(AE9),0))))))) -> 0
C10: 0 | D10: 0 | E10: =(IF(F10=Listas!$B$7,"8",IF(F10=Listas!$B$8,"7",IF(F10=Listas!$B$9,"6",IF(F10=Listas!$B$10,"7",IF(F10=Listas!$B$11,"6.125",IF(F10=Listas!$B$12,"5.250",IF(F10=Listas!$B$6,"0")))))))) -> 0 | F10: 0 | G10: 0 | H10: 0 | I10: 0 | J10: 0 | K10: 0 | L10: 0 | M10: 0 | N10: 0 | O10: 0 | P10: =+(G10*E10)+(H10+I10+J10)+(((K10+L10+O10)*E10/2))+(((M10+N10)*E10)) -> 0 | Q10: =IF(D10=Listas!$B$41,SUM(P10*1227)/1227,0) -> 0 | R10: =IF(D10=Listas!$B$42,SUM(P10*1403)/1227,0) -> 0 | S10: =IF(D10=Listas!$B$43,SUM(P10*1636)/1227,0) -> 0 | T10: =+Q10+R10+S10 -> 0 | U10: =IF(C10=Listas!$B$18,((T10*1227)*23%)+(T10*1227),IF(C10=Listas!$B$19,((T10*1227)*56%)+(T10*1227),IF(C10=Listas!$B$20,((T10*1227)*69%)+(T10*1227),IF(C10=Listas!$B$21,((T10*1227)*31%)+(T10*1227),IF(C10=Listas!$B$22,((T10*1227)*11%)+(T10*1227),IF(C10=Listas!$B$17,((T10*1227)*0%)+(T10*1227)))))))/1227.66 -> 0 | V10: =+U10 -> 0 | X10: 0 | Y10: 0 | Z10: 0 | AA10: 0 | AB10: =(IF(Y10=Listas!$B$41,SUM(IF(Z10=Listas!$B$27,SUM(AA10*1227),IF(Z10=Listas!$B$28,SUM(AA10*1841),IF(Z10=Listas!$B$29,SUM(AA10*2455)))))))/1227 -> 0 | AC10: =(IF(Y10=Listas!$B$42,SUM(IF(Z10=Listas!$B$27,SUM(AA10*1403),IF(Z10=Listas!$B$28,SUM(AA10*2104),IF(Z10=Listas!$B$29,SUM(AA10*2806)))))))/1227 -> 0 | AD10: =(IF(Y10=Listas!$B$43,SUM(IF(Z10=Listas!$B$27,SUM(AA10*1636),IF(Z10=Listas!$B$28,SUM(AA10*2454),IF(Z10=Listas!$B$29,SUM(AA10*3272)))))))/1227 -> 0 | AE10: =SUM(AB10:AD10) -> 0 | AF10: =(IF(X10=Listas!$B$18,+(AE10*23%)+(AE10),IF(X10=Listas!$B$19,+(AE10*56%)+(AE10),IF(X10=Listas!$B$20,+(AE10*103%)+(AE10),IF(X10=Listas!$B$21,+(AE10*31%)+(AE10),IF(X10=Listas!$B$22,+(AE10*11%)+(AE10),IF(X10=Listas!$B$17,+(AE10*0%)+(AE10),0))))))) -> 0
